Workbook

Sheet ISTRUZIONI
A1: IL FILE "MAGAZZINO BCW" DEVE SEMPRE ESSERE UTILIZZATO OFFLINE TRAMITE MICROSOFT EXCEL PER POI ESSERE RICARICATO ONLINE AGGIORNATO AL TERMINE DELL'AGGIORNAMENTO. MODIFICHE ONLINE CAUSEREBBERO ERRORI DI FORMATTAZIONE CHE COMPROMETTONO L'UTILIZZO DEI FOGLI.
A2: THE ‘BCW WAREHOUSE’ FILE MUST ALWAYS BE USED OFFLINE VIA MICROSOFT EXCEL AND THEN RELOADED ONLINE AFTER THE UPDATE IS COMPLETE. ONLINE CHANGES WOULD CAUSE FORMATTING ERRORS THAT WOULD COMPROMISE THE USE OF SHEETS.
A4: FOGLIO INVENTARIO - INVENTORY SHEET
A5: IL FOGLIO "INVENTARIO" SERVE PER INSERIRE LE CATEGORIE DI PRODOTTI ASCRIVIBILI AL MAGAZZINO. QUANDO SI INERISCE UNA NUOVA CATEGORIA BISOGNA TRASCINARE ANCHE LE RELATIVE FORMULE (COLONNE "COSTO - COSTO IMBALLO - COSTO COMPLESSIVO") PER IL CALCOLO DEI TOTALI DEI BENI PRESENTI IN MAGAZZINO CHE FANNO CAPO A TALE CATEGORIA.
A6: THE ‘INVENTORY’ SHEET IS USED TO ENTER THE CATEGORIES OF PRODUCTS IN THE WAREHOUSE. WHEN YOU ENTER A NEW CATEGORY, YOU MUST ALSO DRAG AND DROP THE RELEVANT FORMULAS (COLUMNS ‘COST - PACKAGING COST - TOTAL COST’) TO CALCULATE THE TOTALS OF THE GOODS IN THE WAREHOUSE THAT BELONG TO THAT CATEGORY.
A8: FOGLIO MAGAZZINO - WAREHOUSE SHEET
A9: IL FOGLIO "MAGAZZINO" SERVE PER L'INSERIMENTO DEI SINGOLI BENI ACQUISTATO, I QUALI VANNO INSERITI SCEGLIENDO SEMPRE TRA LE TIPOLOGIE PROPOSTE CON MENU A TENDINA. L'INSERIMENTO DI UN ARMA CON NUMERO DI MATRICOLA, LA QUALE DEVE TRANSITARE DAL REGISTRO DI CARICO-SCARICO, DEVE AVVENIRE INDICANDO UN NUMERO OPERAZIONE PROGRESSIVO E IN ORDINE PER DATA DI CARICO. LA DATA DI CARICO E' LA DATA IN CUI EFFETTIVAMENTE UN ARMA ARRIVA PRESSO IL MAGAZZINO DI GARDONE VAL TROMPIA, E QUESTA DATA PUO' DIFFERIRE DALLA DATA DEL DDT E DALLA DATA DELLA FATTURA. LA DATA DI CARICO DEVE QUINDI ESSERE COMUNICATA DA CHI STA A GARDONE VAL TROMPIA A CHI INSERISCE I DATI. LA REGOLA PIU' IMPORTANTE E' QUELLA DI SEGUIRE UN NUMERO PROGRESSIVO (N. OPERAZIONE)CHE RISPETTI CRONOLOGICAMENTE LE DATE DI CARICO POICHE' IN QUESTO MODO IL REGISTRO DI CARICO SI COMPILERA' AUTOMATICAMENTE SENZA ERRORI E SENZA NECESSITA' DI MODIFICARE A MANO ALCUNA CELLA.
A10: THE ‘’WAREHOUSE‘’ SHEET IS USED FOR THE ENTRY OF INDIVIDUAL PURCHASED GOODS, WHICH MUST ALWAYS BE ENTERED BY CHOOSING FROM THE TYPES PROPOSED IN THE DROP-DOWN MENU. THE ENTRY OF A FIREARM WITH A SERIAL NUMBER, WHICH MUST PASS THROUGH THE LOADING-UNLOADING REGISTER, MUST BE MADE BY INDICATING A PROGRESSIVE OPERATION NUMBER AND IN ORDER BY LOADING DATE. THE LOADING DATE IS THE DATE ON WHICH A FIREARM ACTUALLY ARRIVES AT THE GARDONE VAL TROMPIA WAREHOUSE, AND THIS DATE MAY DIFFER FROM THE DATE OF THE DDT AND THE DATE OF THE INVOICE. THE LOADING DATE MUST THEREFORE BE COMMUNICATED BY THE PERSON IN GARDONE VAL TROMPIA TO THE PERSON ENTERING THE DATA. THE MOST IMPORTANT RULE IS TO FOLLOW A PROGRESSIVE NUMBER (OPERATION NO.) THAT CHRONOLOGICALLY RESPECTS THE LOADING DATES BECAUSE IN THIS WAY THE LOADING REGISTER WILL BE AUTOMATICALLY FILLED IN WITHOUT ERRORS AND WITHOUT THE NEED TO MODIFY ANY CELL BY HAND.
A11: NON E' UN PROBLEMA PRECARICARE A MAGAZZINO DEI BENI ACQUISTATI E NON ANCORA RICEVUTI: INFATTI E' POSSIBILE INSERIRE A MAGAZZINO QUESTI BENI E ANDARE A REGISTRARE IL "N. OPERAZIONE" E LA DATA DI CARICO SOLO IL GIORNO DI EFFETTIVA CONSEGNA; IN QUESTO MODO IL REGISTRO DI CARICO SI COMPILERA' AUTOMATICAMENTE SOLO AL MOMENTO DELL'INDICAZIONE DEL N. OPERAZIONE E DELLA DATA DI EFFETTIVO INGRESSO DEI BENI. PER MANTENERE POI UN ORDINE CRONOLOGICO ANCHE NEL FOGLIO "MAGAZZINO" SARA' POI POSSIBILE TAGLIARE LE RIGHE COSE' AGGIORNATE E INSERIRLE CONSECUTIVAMENTE NEL RISPETTO DELLA CRONOLOGIA DELLE DATE DI CARICO.
A12: IT IS NOT A PROBLEM TO PRE-LOAD IN THE WAREHOUSE GOODS PURCHASED AND NOT YET RECEIVED: IN FACT, IT IS POSSIBLE TO ENTER THESE GOODS IN THE WAREHOUSE AND GO TO RECORD THE ‘OPERATION NO.’ AND THE LOADING DATE ONLY ON THE DAY OF ACTUAL DELIVERY; IN THIS WAY, THE LOADING REGISTER WILL BE AUTOMATICALLY FILLED IN ONLY WHEN THE OPERATION NO. AND THE DATE OF ACTUAL ENTRY OF THE GOODS ARE ENTERED. IN ORDER TO MAINTAIN A CHRONOLOGICAL ORDER EVEN IN THE ‘WAREHOUSE’ SHEET, IT WILL THEN BE POSSIBLE TO CUT THE UPDATED ROWS AND ENTER THEM CONSECUTIVELY IN ACCORDANCE WITH THE CHRONOLOGY OF THE LOADING DATES.
A13: I BENI ACQUISTATI NON DOTATI DI MATRICOLA E NON CONSIDERATI COME "ARMI" (RICAMBI, ACCESSORI, ECC.) DEVONO ESSERE INSERITI CON LE STESSE REGOLE SOPRA DESCRITTE PER LE ARMI, AD ECCEZIONE PER L'INDICAZIONE DEL "N. OPERAZIONE", CAMPO CHE DEVE ESSERE LASCIATO VUOTO. IN QUESTO MODO QUESTI BENI NON TRANSITERANNO DAL FOGLIO DI CARICO E SCARICO. SI CONSIGLIA COMUNQUE DI INSERIRE LA DATA DI CARICO EFFETTIVA E DI RISPETTARE L'ORDINE CRONOLOGICO DI QUESTE, TAGLIANDO E INSERENDO LE RIGHE AL PUNTO CORRETTO.
A14: PURCHASED GOODS THAT DO NOT HAVE A SERIAL NUMBER AND ARE NOT CONSIDERED AS ‘ARMS’ (SPARE PARTS, ACCESSORIES, ETC.) MUST BE ENTERED ACCORDING TO THE SAME RULES DESCRIBED ABOVE FOR ARMS, EXCEPT FOR THE INDICATION OF THE ‘TRANSACTION NO.’, A FIELD WHICH MUST BE LEFT BLANK. IN THIS WAY THESE GOODS WILL NOT PASS THROUGH THE LOADING AND UNLOADING SHEET. HOWEVER, IT IS ADVISABLE TO ENTER THE ACTUAL LOADING DATE AND TO RESPECT THE CHRONOLOGICAL ORDER OF THESE BY CUTTING AND INSERTING THE LINES IN THE CORRECT PLACE.
... A34: IT IS ADVISABLE TO PERIODICALLY CHECK THAT THE ERROR CONTROL CELLS DO NOT RETURN ERROR WARNINGS

Sheet INVENTARIO
B1: =+MAGAZZINO!E1 | D1: =+MAGAZZINO!M1 | E1: =+MAGAZZINO!N1 | F1: =+MAGAZZINO!O1 | H1: MACROCLASSE | J1: =+D1 | K1: =+E1 | L1: =+F1
D2: =+SUMIFS(MAGAZZINO!M$2:M$100000,MAGAZZINO!$A$2:$A$100000,">0",MAGAZZINO!$E$2:$E$100000,INVENTARIO!$B2) | E2: =+SUMIFS(MAGAZZINO!N$2:N$100000,MAGAZZINO!$A$2:$A$100000,">0",MAGAZZINO!$E$2:$E$100000,INVENTARIO!$B2) | F2: =+SUMIFS(MAGAZZINO!O$2:O$100000,MAGAZZINO!$A$2:$A$100000,">0",MAGAZZINO!$E$2:$E$100000,INVENTARIO!$B2)
B3: ACCESSORI | D3: =+SUMIFS(MAGAZZINO!M$2:M$100000,MAGAZZINO!$A$2:$A$100000,">0",MAGAZZINO!$E$2:$E$100000,INVENTARIO!$B3) | E3: =+SUMIFS(MAGAZZINO!N$2:N$100000,MAGAZZINO!$A$2:$A$100000,">0",MAGAZZINO!$E$2:$E$100000,INVENTARIO!$B3) | F3: =+SUMIFS(MAGAZZINO!O$2:O$100000,MAGAZZINO!$A$2:$A$100000,">0",MAGAZZINO!$E$2:$E$100000,INVENTARIO!$B3) | H3: ACCESSORI | J3: =+D3 | K3: =+E3 | L3: =+F3
B4: CANNA PER CARABINA | D4: =+SUMIFS(MAGAZZINO!M$2:M$100000,MAGAZZINO!$A$2:$A$100000,">0",MAGAZZINO!$E$2:$E$100000,INVENTARIO!$B4) | E4: =+SUMIFS(MAGAZZINO!N$2:N$100000,MAGAZZINO!$A$2:$A$100000,">0",MAGAZZINO!$E$2:$E$100000,INVENTARIO!$B4) | F4: =+SUMIFS(MAGAZZINO!O$2:O$100000,MAGAZZINO!$A$2:$A$100000,">0",MAGAZZINO!$E$2:$E$100000,INVENTARIO!$B4) | H4: CANNE | J4: =+SUM(D4:D11) | K4: =+SUM(E4:E11) | L4: =+SUM(F4:F11)
B5: CANNA PER CARABINA AD ARIA COMPRESSA | D5: =+SUMIFS(MAGAZZINO!M$2:M$100000,MAGAZZINO!$A$2:$A$100000,">0",MAGAZZINO!$E$2:$E$100000,INVENTARIO!$B5) | E5: =+SUMIFS(MAGAZZINO!N$2:N$100000,MAGAZZINO!$A$2:$A$100000,">0",MAGAZZINO!$E$2:$E$100000,INVENTARIO!$B5) | F5: =+SUMIFS(MAGAZZINO!O$2:O$100000,MAGAZZINO!$A$2:$A$100000,">0",MAGAZZINO!$E$2:$E$100000,INVENTARIO!$B5)
B6: CANNA PER FUCILE DOPPIETTA | D6: =+SUMIFS(MAGAZZINO!M$2:M$100000,MAGAZZINO!$A$2:$A$100000,">0",MAGAZZINO!$E$2:$E$100000,INVENTARIO!$B6) | E6: =+SUMIFS(MAGAZZINO!N$2:N$100000,MAGAZZINO!$A$2:$A$100000,">0",MAGAZZINO!$E$2:$E$100000,INVENTARIO!$B6) | F6: =+SUMIFS(MAGAZZINO!O$2:O$100000,MAGAZZINO!$A$2:$A$100000,">0",MAGAZZINO!$E$2:$E$100000,INVENTARIO!$B6)
B7: CANNA PER FUCILE MONOCANNA | D7: =+SUMIFS(MAGAZZINO!M$2:M$100000,MAGAZZINO!$A$2:$A$100000,">0",MAGAZZINO!$E$2:$E$100000,INVENTARIO!$B7) | E7: =+SUMIFS(MAGAZZINO!N$2:N$100000,MAGAZZINO!$A$2:$A$100000,">0",MAGAZZINO!$E$2:$E$100000,INVENTARIO!$B7) | F7: =+SUMIFS(MAGAZZINO!O$2:O$100000,MAGAZZINO!$A$2:$A$100000,">0",MAGAZZINO!$E$2:$E$100000,INVENTARIO!$B7)
B8: CANNA PER FUCILE SEMIAUTOMATICO | D8: =+SUMIFS(MAGAZZINO!M$2:M$100000,MAGAZZINO!$A$2:$A$100000,">0",MAGAZZINO!$E$2:$E$100000,INVENTARIO!$B8) | E8: =+SUMIFS(MAGAZZINO!N$2:N$100000,MAGAZZINO!$A$2:$A$100000,">0",MAGAZZINO!$E$2:$E$100000,INVENTARIO!$B8) | F8: =+SUMIFS(MAGAZZINO!O$2:O$100000,MAGAZZINO!$A$2:$A$100000,">0",MAGAZZINO!$E$2:$E$100000,INVENTARIO!$B8)
B9: CANNA PER FUCILE SOVRAPPOSTO | D9: =+SUMIFS(MAGAZZINO!M$2:M$100000,MAGAZZINO!$A$2:$A$100000,">0",MAGAZZINO!$E$2:$E$100000,INVENTARIO!$B9) | E9: =+SUMIFS(MAGAZZINO!N$2:N$100000,MAGAZZINO!$A$2:$A$100000,">0",MAGAZZINO!$E$2:$E$100000,INVENTARIO!$B9) | F9: =+SUMIFS(MAGAZZINO!O$2:O$100000,MAGAZZINO!$A$2:$A$100000,">0",MAGAZZINO!$E$2:$E$100000,INVENTARIO!$B9)
B10: CANNA PER PISTOLA | D10: =+SUMIFS(MAGAZZINO!M$2:M$100000,MAGAZZINO!$A$2:$A$100000,">0",MAGAZZINO!$E$2:$E$100000,INVENTARIO!$B10) | E10: =+SUMIFS(MAGAZZINO!N$2:N$100000,MAGAZZINO!$A$2:$A$100000,">0",MAGAZZINO!$E$2:$E$100000,INVENTARIO!$B10) | F10: =+SUMIFS(MAGAZZINO!O$2:O$100000,MAGAZZINO!$A$2:$A$100000,">0",MAGAZZINO!$E$2:$E$100000,INVENTARIO!$B10)
B11: CANNA RIGATA | D11: =+SUMIFS(MAGAZZINO!M$2:M$100000,MAGAZZINO!$A$2:$A$100000,">0",MAGAZZINO!$E$2:$E$100000,INVENTARIO!$B11) | E11: =+SUMIFS(MAGAZZINO!N$2:N$100000,MAGAZZINO!$A$2:$A$100000,">0",MAGAZZINO!$E$2:$E$100000,INVENTARIO!$B11) | F11: =+SUMIFS(MAGAZZINO!O$2:O$100000,MAGAZZINO!$A$2:$A$100000,">0",MAGAZZINO!$E$2:$E$100000,INVENTARIO!$B11)
B12: CARABINA | D12: =+SUMIFS(MAGAZZINO!M$2:M$100000,MAGAZZINO!$A$2:$A$100000,">0",MAGAZZINO!$E$2:$E$100000,INVENTARIO!$B12) | E12: =+SUMIFS(MAGAZZINO!N$2:N$100000,MAGAZZINO!$A$2:$A$100000,">0",MAGAZZINO!$E$2:$E$100000,INVENTARIO!$B12) | F12: =+SUMIFS(MAGAZZINO!O$2:O$100000,MAGAZZINO!$A$2:$A$100000,">0",MAGAZZINO!$E$2:$E$100000,INVENTARIO!$B12) | H12: CARABINE | J12: =+SUM(D12:D18) | K12: =+SUM(E12:E18) | L12: =+SUM(F12:F18)
B13: CARABINA A LEVA | D13: =+SUMIFS(MAGAZZINO!M$2:M$100000,MAGAZZINO!$A$2:$A$100000,">0",MAGAZZINO!$E$2:$E$100000,INVENTARIO!$B13) | E13: =+SUMIFS(MAGAZZINO!N$2:N$100000,MAGAZZINO!$A$2:$A$100000,">0",MAGAZZINO!$E$2:$E$100000,INVENTARIO!$B13) | F13: =+SUMIFS(MAGAZZINO!O$2:O$100000,MAGAZZINO!$A$2:$A$100000,">0",MAGAZZINO!$E$2:$E$100000,INVENTARIO!$B13)
B14: CARABINA SEMIAUTOMATICA | D14: =+SUMIFS(MAGAZZINO!M$2:M$100000,MAGAZZINO!$A$2:$A$100000,">0",MAGAZZINO!$E$2:$E$100000,INVENTARIO!$B14) | E14: =+SUMIFS(MAGAZZINO!N$2:N$100000,MAGAZZINO!$A$2:$A$100000,">0",MAGAZZINO!$E$2:$E$100000,INVENTARIO!$B14) | F14: =+SUMIFS(MAGAZZINO!O$2:O$100000,MAGAZZINO!$A$2:$A$100000,">0",MAGAZZINO!$E$2:$E$100000,INVENTARIO!$B14)
B15: CARABINA AD ARIA COMPRESSA | D15: =+SUMIFS(MAGAZZINO!M$2:M$100000,MAGAZZINO!$A$2:$A$100000,">0",MAGAZZINO!$E$2:$E$100000,INVENTARIO!$B15) | E15: =+SUMIFS(MAGAZZINO!N$2:N$100000,MAGAZZINO!$A$2:$A$100000,">0",MAGAZZINO!$E$2:$E$100000,INVENTARIO!$B15) | F15: =+SUMIFS(MAGAZZINO!O$2:O$100000,MAGAZZINO!$A$2:$A$100000,">0",MAGAZZINO!$E$2:$E$100000,INVENTARIO!$B15)
B16: CARABINA AD ARIA COMPRESSA PCP | D16: =+SUMIFS(MAGAZZINO!M$2:M$100000,MAGAZZINO!$A$2:$A$100000,">0",MAGAZZINO!$E$2:$E$100000,INVENTARIO!$B16) | E16: =+SUMIFS(MAGAZZINO!N$2:N$100000,MAGAZZINO!$A$2:$A$100000,">0",MAGAZZINO!$E$2:$E$100000,INVENTARIO!$B16) | F16: =+SUMIFS(MAGAZZINO!O$2:O$100000,MAGAZZINO!$A$2:$A$100000,">0",MAGAZZINO!$E$2:$E$100000,INVENTARIO!$B16)
B17: CARABINA MONOCOLPO | D17: =+SUMIFS(MAGAZZINO!M$2:M$100000,MAGAZZINO!$A$2:$A$100000,">0",MAGAZZINO!$E$2:$E$100000,INVENTARIO!$B17) | E17: =+SUMIFS(MAGAZZINO!N$2:N$100000,MAGAZZINO!$A$2:$A$100000,">0",MAGAZZINO!$E$2:$E$100000,INVENTARIO!$B17) | F17: =+SUMIFS(MAGAZZINO!O$2:O$100000,MAGAZZINO!$A$2:$A$100000,">0",MAGAZZINO!$E$2:$E$100000,INVENTARIO!$B17)
B18: CARABINA AD OTTURATORE | D18: =+SUMIFS(MAGAZZINO!M$2:M$100000,MAGAZZINO!$A$2:$A$100000,">0",MAGAZZINO!$E$2:$E$100000,INVENTARIO!$B18) | E18: =+SUMIFS(MAGAZZINO!N$2:N$100000,MAGAZZINO!$A$2:$A$100000,">0",MAGAZZINO!$E$2:$E$100000,INVENTARIO!$B18) | F18: =+SUMIFS(MAGAZZINO!O$2:O$100000,MAGAZZINO!$A$2:$A$100000,">0",MAGAZZINO!$E$2:$E$100000,INVENTARIO!$B18)
B19: DOPPIETTA A CANNE RIGATE | D19: =+SUMIFS(MAGAZZINO!M$2:M$100000,MAGAZZINO!$A$2:$A$100000,">0",MAGAZZINO!$E$2:$E$100000,INVENTARIO!$B19) | E19: =+SUMIFS(MAGAZZINO!N$2:N$100000,MAGAZZINO!$A$2:$A$100000,">0",MAGAZZINO!$E$2:$E$100000,INVENTARIO!$B19) | F19: =+SUMIFS(MAGAZZINO!O$2:O$100000,MAGAZZINO!$A$2:$A$100000,">0",MAGAZZINO!$E$2:$E$100000,INVENTARIO!$B19) | H19: DOPPIETTA | J19: =D19 | K19: =E19 | L19: =F19
B20: FUCILE A POMPA | D20: =+SUMIFS(MAGAZZINO!M$2:M$100000,MAGAZZINO!$A$2:$A$100000,">0",MAGAZZINO!$E$2:$E$100000,INVENTARIO!$B20) | E20: =+SUMIFS(MAGAZZINO!N$2:N$100000,MAGAZZINO!$A$2:$A$100000,">0",MAGAZZINO!$E$2:$E$100000,INVENTARIO!$B20) | F20: =+SUMIFS(MAGAZZINO!O$2:O$100000,MAGAZZINO!$A$2:$A$100000,">0",MAGAZZINO!$E$2:$E$100000,INVENTARIO!$B20) | H20: FUCILI | J20: =+SUM(D20:D29) | K20: =+SUM(E20:E29) | L20: =+SUM(F20:F29)
B21: FUCILE AVANCARICA | D21: =+SUMIFS(MAGAZZINO!M$2:M$100000,MAGAZZINO!$A$2:$A$100000,">0",MAGAZZINO!$E$2:$E$100000,INVENTARIO!$B21) | E21: =+SUMIFS(MAGAZZINO!N$2:N$100000,MAGAZZINO!$A$2:$A$100000,">0",MAGAZZINO!$E$2:$E$100000,INVENTARIO!$B21) | F21: =+SUMIFS(MAGAZZINO!O$2:O$100000,MAGAZZINO!$A$2:$A$100000,">0",MAGAZZINO!$E$2:$E$100000,INVENTARIO!$B21)
B22: FUCILE DOPPIETTA | D22: =+SUMIFS(MAGAZZINO!M$2:M$100000,MAGAZZINO!$A$2:$A$100000,">0",MAGAZZINO!$E$2:$E$100000,INVENTARIO!$B22) | E22: =+SUMIFS(MAGAZZINO!N$2:N$100000,MAGAZZINO!$A$2:$A$100000,">0",MAGAZZINO!$E$2:$E$100000,INVENTARIO!$B22) | F22: =+SUMIFS(MAGAZZINO!O$2:O$100000,MAGAZZINO!$A$2:$A$100000,">0",MAGAZZINO!$E$2:$E$100000,INVENTARIO!$B22)
B23: FUCILE DOPPIETTA CANI ESTERNI | D23: =+SUMIFS(MAGAZZINO!M$2:M$100000,MAGAZZINO!$A$2:$A$100000,">0",MAGAZZINO!$E$2:$E$100000,INVENTARIO!$B23) | E23: =+SUMIFS(MAGAZZINO!N$2:N$100000,MAGAZZINO!$A$2:$A$100000,">0",MAGAZZINO!$E$2:$E$100000,INVENTARIO!$B23) | F23: =+SUMIFS(MAGAZZINO!O$2:O$100000,MAGAZZINO!$A$2:$A$100000,">0",MAGAZZINO!$E$2:$E$100000,INVENTARIO!$B23)
B24: FUCILE DOPPIETTA CANI INTERNI | D24: =+SUMIFS(MAGAZZINO!M$2:M$100000,MAGAZZINO!$A$2:$A$100000,">0",MAGAZZINO!$E$2:$E$100000,INVENTARIO!$B24) | E24: =+SUMIFS(MAGAZZINO!N$2:N$100000,MAGAZZINO!$A$2:$A$100000,">0",MAGAZZINO!$E$2:$E$100000,INVENTARIO!$B24) | F24: =+SUMIFS(MAGAZZINO!O$2:O$100000,MAGAZZINO!$A$2:$A$100000,">0",MAGAZZINO!$E$2:$E$100000,INVENTARIO!$B24)
B25: FUCILE DOPPIETTA AVANCARICA | D25: =+SUMIFS(MAGAZZINO!M$2:M$100000,MAGAZZINO!$A$2:$A$100000,">0",MAGAZZINO!$E$2:$E$100000,INVENTARIO!$B25) | E25: =+SUMIFS(MAGAZZINO!N$2:N$100000,MAGAZZINO!$A$2:$A$100000,">0",MAGAZZINO!$E$2:$E$100000,INVENTARIO!$B25) | F25: =+SUMIFS(MAGAZZINO!O$2:O$100000,MAGAZZINO!$A$2:$A$100000,">0",MAGAZZINO!$E$2:$E$100000,INVENTARIO!$B25)
B26: FUCILE MONOCANNA | D26: =+SUMIFS(MAGAZZINO!M$2:M$100000,MAGAZZINO!$A$2:$A$100000,">0",MAGAZZINO!$E$2:$E$100000,INVENTARIO!$B26) | E26: =+SUMIFS(MAGAZZINO!N$2:N$100000,MAGAZZINO!$A$2:$A$100000,">0",MAGAZZINO!$E$2:$E$100000,INVENTARIO!$B26) | F26: =+SUMIFS(MAGAZZINO!O$2:O$100000,MAGAZZINO!$A$2:$A$100000,">0",MAGAZZINO!$E$2:$E$100000,INVENTARIO!$B26)
B27: FUCILE SEMIAUTOMATICO | D27: =+SUMIFS(MAGAZZINO!M$2:M$100000,MAGAZZINO!$A$2:$A$100000,">0",MAGAZZINO!$E$2:$E$100000,INVENTARIO!$B27) | E27: =+SUMIFS(MAGAZZINO!N$2:N$100000,MAGAZZINO!$A$2:$A$100000,">0",MAGAZZINO!$E$2:$E$100000,INVENTARIO!$B27) | F27: =+SUMIFS(MAGAZZINO!O$2:O$100000,MAGAZZINO!$A$2:$A$100000,">0",MAGAZZINO!$E$2:$E$100000,INVENTARIO!$B27)
B28: FUCILE AD OTTURATORE | D28: =+SUMIFS(MAGAZZINO!M$2:M$100000,MAGAZZINO!$A$2:$A$100000,">0",MAGAZZINO!$E$2:$E$100000,INVENTARIO!$B28) | E28: =+SUMIFS(MAGAZZINO!N$2:N$100000,MAGAZZINO!$A$2:$A$100000,">0",MAGAZZINO!$E$2:$E$100000,INVENTARIO!$B28) | F28: =+SUMIFS(MAGAZZINO!O$2:O$100000,MAGAZZINO!$A$2:$A$100000,">0",MAGAZZINO!$E$2:$E$100000,INVENTARIO!$B28)
B29: FUCILE SOVRAPPOSTO | D29: =+SUMIFS(MAGAZZINO!M$2:M$100000,MAGAZZINO!$A$2:$A$100000,">0",MAGAZZINO!$E$2:$E$100000,INVENTARIO!$B29) | E29: =+SUMIFS(MAGAZZINO!N$2:N$100000,MAGAZZINO!$A$2:$A$100000,">0",MAGAZZINO!$E$2:$E$100000,INVENTARIO!$B29) | F29: =+SUMIFS(MAGAZZINO!O$2:O$100000,MAGAZZINO!$A$2:$A$100000,">0",MAGAZZINO!$E$2:$E$100000,INVENTARIO!$B29)
B30: PISTOLA AVANCARICA | D30: =+SUMIFS(MAGAZZINO!M$2:M$100000,MAGAZZINO!$A$2:$A$100000,">0",MAGAZZINO!$E$2:$E$100000,INVENTARIO!$B30) | E30: =+SUMIFS(MAGAZZINO!N$2:N$100000,MAGAZZINO!$A$2:$A$100000,">0",MAGAZZINO!$E$2:$E$100000,INVENTARIO!$B30) | F30: =+SUMIFS(MAGAZZINO!O$2:O$100000,MAGAZZINO!$A$2:$A$100000,">0",MAGAZZINO!$E$2:$E$100000,INVENTARIO!$B30) | H30: PISTOLE | J30: =+SUM(D30:D32) | K30: =+SUM(E30:E32) | L30: =+SUM(F30:F32)
B31: PISTOLA SEMIAUTOMATICA | D31: =+SUMIFS(MAGAZZINO!M$2:M$100000,MAGAZZINO!$A$2:$A$100000,">0",MAGAZZINO!$E$2:$E$100000,INVENTARIO!$B31) | E31: =+SUMIFS(MAGAZZINO!N$2:N$100000,MAGAZZINO!$A$2:$A$100000,">0",MAGAZZINO!$E$2:$E$100000,INVENTARIO!$B31) | F31: =+SUMIFS(MAGAZZINO!O$2:O$100000,MAGAZZINO!$A$2:$A$100000,">0",MAGAZZINO!$E$2:$E$100000,INVENTARIO!$B31)
B32: PISTOLA POMPA | D32: =+SUMIFS(MAGAZZINO!M$2:M$100000,MAGAZZINO!$A$2:$A$100000,">0",MAGAZZINO!$E$2:$E$100000,INVENTARIO!$B32) | E32: =+SUMIFS(MAGAZZINO!N$2:N$100000,MAGAZZINO!$A$2:$A$100000,">0",MAGAZZINO!$E$2:$E$100000,INVENTARIO!$B32) | F32: =+SUMIFS(MAGAZZINO!O$2:O$100000,MAGAZZINO!$A$2:$A$100000,">0",MAGAZZINO!$E$2:$E$100000,INVENTARIO!$B32)
B33: REVOLVER | D33: =+SUMIFS(MAGAZZINO!M$2:M$100000,MAGAZZINO!$A$2:$A$100000,">0",MAGAZZINO!$E$2:$E$100000,INVENTARIO!$B33) | E33: =+SUMIFS(MAGAZZINO!N$2:N$100000,MAGAZZINO!$A$2:$A$100000,">0",MAGAZZINO!$E$2:$E$100000,INVENTARIO!$B33) | F33: =+SUMIFS(MAGAZZINO!O$2:O$100000,MAGAZZINO!$A$2:$A$100000,">0",MAGAZZINO!$E$2:$E$100000,INVENTARIO!$B33) | H33: REVOLVER | J33: =+D33 | K33: =+E33 | L33: =+F33
B34: CARCASSA | D34: =+SUMIFS(MAGAZZINO!M$2:M$100000,MAGAZZINO!$A$2:$A$100000,">0",MAGAZZINO!$E$2:$E$100000,INVENTARIO!$B34) | E34: =+SUMIFS(MAGAZZINO!N$2:N$100000,MAGAZZINO!$A$2:$A$100000,">0",MAGAZZINO!$E$2:$E$100000,INVENTARIO!$B35) | F34: =+SUMIFS(MAGAZZINO!O$2:O$100000,MAGAZZINO!$A$2:$A$100000,">0",MAGAZZINO!$E$2:$E$100000,INVENTARIO!$B34) | H34: CARCASSA | J34: =+D34 | K34: =+E34 | L34: =+F34
D36: =SUM(D2:D35) | E36: =SUM(E2:E35) | F36: =SUM(F2:F35) | J36: =SUM(J2:J35) | K36: =SUM(K2:K35) | L36: =SUM(L2:L35)
J37: =+IF(D36=J36,"OK","ERRORE") | K37: =+IF(E36=K36,"OK","ERRORE") | L37: =+IF(F36=L36,"OK","ERRORE")
B45: ATTENZIONE: QUANDO SI INSERISCE UNA NUOVA TIPOLOGIA FARLO SEMPRE TRA LA PRIMA E L'ULTIMA RIGA APPOSITAMENTE COLORATE IN GIALLO
B46: ATTENTION: WHEN ENTERING A NEW TYPE, ALWAYS DO SO BETWEEN THE FIRST AND LAST LINES SPECIALLY COLOURED IN YELLOW
B47: ATTENZIONE: QUANDO SI INSERISCE UNA NUOVA TIPOLOGIA FARLO SEMPRE RISPETTANDO L'ORDINE ALFABETICO, IN MODO CHE IL MENU A TENDINA NEL FOGLIO "MAGAZZINO" RESTITUISCA LE PROPOSTE IN ORDINE
B48: ATTENTION: WHEN ENTERING A NEW TYPE, ALWAYS DO SO IN ALPHABETICAL ORDER, SO THAT THE DROP-DOWN MENU IN THE ‘WAREHOUSE’ SHEET RETURNS THE PROPOSALS IN ORDER
...

Sheet MAGAZZINO
A1: GIACENZA | B1: NUMERO OPERAZIONE | C1: DATA DI CARICO | D1: QUANTITA' | E1: TIPOLOGIA | F1: CALIBRO | G1: MARCA ARMA | H1: MODELLO | I1: MATR. ARMA | J1: MATR. CANNA | K1: MATR. AGG. | L1: FORNITORE | M1: COSTO | N1: COSTO IMBALLO | O1: COSTO COMPL. | P1: DATA DDT | Q1: DATA FATTURA | R1: PREZZO DI VENDITA | S1: V | T1: N. ATA | U1: DATA DI SCARICO | V1: N. FATTURA | W1: DATA FATTURA | X1: CLIENTE
A2: =+D2-S2 | O2: =+M2+N2
A3: =+D3-S3 | C3: 45350 | D3: 1 | E3: FUCILE A POMPA | F3: 12 | G3: WINCHESTER | H3: SXP DEFENDER | I3: 12AZR13526 | J3: N/D | K3: N/D | L3: MANTOVARMI SNC DI BERGHAMASCHI FABIO & C | M3: 280 | O3: =+M3+N3 | R3: 299 | S3: 1 | T3: CA42796IR | U3: 45821 | V3: 11 | W3: 45821 | X3: PHILIPPOS COSTANTINIDES TRADING CO. LTD
A4: =+D4-S4 | C4: 45350 | D4: 1 | E4: FUCILE MONOCANNA | F4: 16 | G4: BERETTA | H4: N/D | I4: 90947 | J4: N/D | K4: N/D | L4: ARMERIA LENZERINI SAS | M4: 20 | O4: =+M4+N4 | R4: 30 | S4: 1 | T4: CA42796IR | U4: 45821 | V4: 8 | W4: 45821 | X4: PHILIPPOS COSTANTINIDES TRADING CO. LTD
A5: =+D5-S5 | C5: 45350 | D5: 1 | E5: CARABINA AD ARIA COMPRESSA | F5: 4,5 | G5: DIANA | H5: N/D | I5: 311396 | J5: N/D | K5: N/D | L5: ARMERIA LENZERINI SAS | M5: 15 | O5: =+M5+N5 | R5: 25 | S5: 1 | T5: CA42796IR | U5: 45821 | V5: 16 | W5: 45821 | X5: PHILIPPOS COSTANTINIDES TRADING CO. LTD
A6: =+D6-S6 | C6: 45350 | D6: 1 | E6: CARABINA AD ARIA COMPRESSA | F6: 4,5 | G6: DIANA | H6: N/D | I6: 11755 | J6: N/D | K6: N/D | L6: ARMERIA LENZERINI SAS | M6: 15 | O6: =+M6+N6 | R6: 25 | S6: 1 | T6: CA42796IR | U6: 45821 | V6: 16 | W6: 45821 | X6: PHILIPPOS COSTANTINIDES TRADING CO. LTD
A7: =+D7-S7 | C7: 45350 | D7: 1 | E7: CARABINA AD ARIA COMPRESSA | F7: 4,5 | G7: DIANA | H7: N/D | I7: 70149373 | J7: N/D | K7: N/D | L7: ARMERIA LENZERINI SAS | M7: 15 | O7: =+M7+N7 | R7: 25 | S7: 1 | T7: CA42796IR | U7: 45821 | V7: 16 | W7: 45821 | X7: PHILIPPOS COSTANTINIDES TRADING CO. LTD
A8: =+D8-S8 | C8: 45350 | D8: 1 | E8: CARABINA AD ARIA COMPRESSA | F8: 4,5 | G8: SHANGAI | H8: N/D | I8: 1038 | J8: N/D | K8: N/D | L8: ARMERIA LENZERINI SAS | M8: 15 | O8: =+M8+N8 | R8: 25 | S8: 1 | T8: CA42796IR | U8: 45821 | V8: 16 | W8: 45821 | X8: PHILIPPOS COSTANTINIDES TRADING CO. LTD
A9: =+D9-S9 | C9: 45350 | D9: 1 | E9: CARABINA AD ARIA COMPRESSA | F9: 4,5 | G9: WALTHER | H9: N/D | I9: 81024 | J9: N/D | K9: N/D | L9: ARMERIA LENZERINI SAS | M9: 15 | O9: =+M9+N9 | R9: 25 | S9: 1 | T9: CA42796IR | U9: 45821 | V9: 16 | W9: 45821 | X9: PHILIPPOS COSTANTINIDES TRADING CO. LTD
A10: =+D10-S10 | C10: 45350 | D10: 1 | E10: CARABINA AD ARIA COMPRESSA | F10: 4,5 | G10: DIANA | H10: N/D | I10: 97435 | J10: N/D | K10: N/D | L10: ARMERIA LENZERINI SAS | M10: 15 | O10: =+M10+N10 | R10: 25 | S10: 1 | T10: CA42796IR | U10: 45821 | V10: 16 | W10: 45821 | X10: PHILIPPOS COSTANTINIDES TRADING CO. LTD
A11: =+D11-S11 | C11: 45350 | D11: 1 | E11: CARABINA AD ARIA COMPRESSA | F11: 4,5 | G11: BSA | H11: N/D | I11: GM04111 | J11: N/D | K11: N/D | L11: ARMERIA LENZERINI SAS | M11: 15 | O11: =+M11+N11 | R11: 25 | S11: 1 | T11: CA42796IR | U11: 45821 | V11: 16 | W11: 45821 | X11: PHILIPPOS COSTANTINIDES TRADING CO. LTD
A12: =+D12-S12 | C12: 45350 | D12: 1 | E12: CARABINA AD ARIA COMPRESSA | F12: 4,5 | G12: GAMO | H12: N/D | I12: 487078 | J12: N/D | K12: N/D | L12: ARMERIA LENZERINI SAS | M12: 15 | O12: =+M12+N12 | R12: 25 | S12: 1 | T12: CA42796IR | U12: 45821 | V12: 16 | W12: 45821 | X12: PHILIPPOS COSTANTINIDES TRADING CO. LTD
A13: =+D13-S13 | C13: 45350 | D13: 1 | E13: CARABINA AD ARIA COMPRESSA | F13: 4,5 | G13: WEIHRAUCH | H13: HW77 | I13: 1486895 | J13: N/D | K13: N/D | L13: ARMERIA LENZERINI SAS | M13: 50 | O13: =+M13+N13 | R13: 60 | S13: 1 | T13: CA42796IR | U13: 45821 | V13: 16 | W13: 45821 | X13: PHILIPPOS COSTANTINIDES TRADING CO. LTD
A14: =+D14-S14 | C14: 45350 | D14: 1 | E14: CARABINA AD ARIA COMPRESSA | F14: 4,5 | G14: WEIHRAUCH | H14: N/D | I14: 225729 | J14: N/D | K14: N/D | L14: ARMERIA LENZERINI SAS | M14: 15 | O14: =+M14+N14 | R14: 25 | S14: 1 | T14: CA42796IR | U14: 45821 | V14: 16 | W14: 45821 | X14: PHILIPPOS COSTANTINIDES TRADING CO. LTD
A15: =+D15-S15 | C15: 45350 | D15: 1 | E15: CARABINA AD ARIA COMPRESSA | F15: 4,5 | G15: WEIHRAUCH | H15: N/D | I15: 2203552 | J15: N/D | K15: N/D | L15: ARMERIA LENZERINI SAS | M15: 15 | O15: =+M15+N15 | R15: 25 | S15: 1 | T15: CA42796IR | U15: 45821 | V15: 16 | W15: 45821 | X15: PHILIPPOS COSTANTINIDES TRADING CO. LTD
A16: =+D16-S16 | C16: 45350 | D16: 1 | E16: FUCILE SOVRAPPOSTO | F16: 16 | G16: PASTER | H16: N/D | I16: 51 | J16: N/D | K16: N/D | L16: ARMERIA LENZERINI SAS | M16: 100 | O16: =+M16+N16 | R16: 115 | S16: 1 | T16: CA42796IR | U16: 45821 | V16: 10 | W16: 45821 | X16: PHILIPPOS COSTANTINIDES TRADING CO. LTD
A17: =+D17-S17 | C17: 45379 | D17: 1 | E17: PISTOLA SEMIAUTOMATICA | F17: 9X19 | G17: H&K | H17: SFP9-SF | I17: 218-040943 | J17: N/D | K17: N/D | L17: TFC SRL | M17: 589 | O17: =+M17+N17 | R17: 665.5 | S17: 1 | T17: 6B/2025/5S | U17: 45963 | V17: 32 | W17: 45963 | X17: BIN HUMAID NATIONAL TRADING CO
A18: =+D18-S18 | C18: 45379 | D18: 1 | E18: PISTOLA SEMIAUTOMATICA | F18: 9X19 | G18: H&K | H18: SFP9-SF | I18: 218-040941 | J18: N/D | K18: N/D | L18: TFC SRL | M18: 589 | O18: =+M18+N18 | R18: 665.5 | S18: 1 | T18: 6B/2025/5S | U18: 45963 | V18: 32 | W18: 45963 | X18: BIN HUMAID NATIONAL TRADING CO
A19: =+D19-S19 | C19: 45379 | D19: 1 | E19: PISTOLA SEMIAUTOMATICA | F19: 9X19 | G19: H&K | H19: SFP9-SF | I19: 218-040929 | J19: N/D | K19: N/D | L19: TFC SRL | M19: 589 | O19: =+M19+N19 | R19: 665.5 | S19: 1 | T19: 6B/2025/5S | U19: 45963 | V19: 32 | W19: 45963 | X19: BIN HUMAID NATIONAL TRADING CO
A20: =+D20-S20 | C20: 45379 | D20: 1 | E20: PISTOLA SEMIAUTOMATICA | F20: 9X19 | G20: H&K | H20: SFP9-SF | I20: 218-040939 | J20: N/D | K20: N/D | L20: TFC SRL | M20: 589 | O20: =+M20+N20 | R20: 665.5 | S20: 1 | T20: 6B/2025/5S | U20: 45963 | V20: 32 | W20: 45963 | X20: BIN HUMAID NATIONAL TRADING CO
A21: =+D21-S21 | C21: 45379 | D21: 1 | E21: PISTOLA SEMIAUTOMATICA | F21: 9X19 | G21: H&K | H21: SFP9-SF | I21: 218-040926 | J21: N/D | K21: N/D | L21: TFC SRL | M21: 589 | O21: =+M21+N21 | R21: 665.5 | S21: 1 | T21: 6B/2025/5S | U21: 45963 | V21: 32 | W21: 45963 | X21: BIN HUMAID NATIONAL TRADING CO
A22: =+D22-S22 | C22: 45379 | D22: 1 | E22: PISTOLA SEMIAUTOMATICA | F22: 9X19 | G22: H&K | H22: SFP9-SF | I22: 218-040932 | J22: N/D | K22: N/D | L22: TFC SRL | M22: 589 | O22: =+M22+N22 | R22: 665.5 | S22: 1 | T22: 6B/2025/5S | U22: 45963 | V22: 32 | W22: 45963 | X22: BIN HUMAID NATIONAL TRADING CO
A23: =+D23-S23 | C23: 45379 | D23: 1 | E23: PISTOLA SEMIAUTOMATICA | F23: 9X19 | G23: H&K | H23: SFP9-SF | I23: 218-040927 | J23: N/D | K23: N/D | L23: TFC SRL | M23: 589 | O23: =+M23+N23 | R23: 665.5 | S23: 1 | T23: 6B/2025/5S | U23: 45963 | V23: 32 | W23: 45963 | X23: BIN HUMAID NATIONAL TRADING CO
A24: =+D24-S24 | C24: 45390 | D24: 1 | E24: PISTOLA SEMIAUTOMATICA | F24: 9X21 | G24: BERETTA | H24: PX4 DELUXE | I24: PJ00151 | J24: N/D | K24: N/D | L24: DALBALCON SRL | M24: 950 | O24: =+M24+N24 | R24: 998 | S24: 1 | T24: CA04954OS | U24: 45874 | V24: 25 | W24: 45874 | X24: PHILIPPOS COSTANTINIDES TRADING CO. LTD
A25: =+D25-S25 | C25: 45390 | D25: 1 | E25: PISTOLA SEMIAUTOMATICA | F25: 9X21 | G25: BERETTA | H25: PX4 DELUXE | I25: PJ00121 | J25: N/D | K25: N/D | L25: DALBALCON SRL | M25: 950 | O25: =+M25+N25 | R25: 998 | S25: 1 | T25: CA04954OS | U25: 45874 | V25: 25 | W25: 45874 | X25: PHILIPPOS COSTANTINIDES TRADING CO. LTD
A26: =+D26-S26 | C26: 45390 | D26: 1 | E26: FUCILE SOVRAPPOSTO | F26: 12 | G26: POLI | H26: N/D | I26: 1014 | J26: N/D | K26: N/D | L26: MANTOVARMI SNC DI BERGHAMASCHI FABIO & C | M26: 112 | O26: =+M26+N26 | R26: 120 | S26: 1 | T26: CA42796IR | U26: 45821 | V26: 9 | W26: 45821 | X26: PHILIPPOS COSTANTINIDES TRADING CO. LTD
A27: =+D27-S27 | C27: 45390 | D27: 1 | E27: FUCILE DOPPIETTA | F27: 12 | G27: LIEGE | H27: N/D | I27: 139227 | J27: N/D | K27: N/D | L27: MANTOVARMI SNC DI BERGHAMASCHI FABIO & C | M27: 162 | O27: =+M27+N27 | R27: 100 | S27: 1 | T27: CA42796IR | U27: 45821 | V27: 14 | W27: 45821 | X27: PHILIPPOS COSTANTINIDES TRADING CO. LTD
A28: =+D28-S28 | C28: 45390 | D28: 1 | E28: FUCILE DOPPIETTA | F28: 12 | G28: ARTIGIANALE | H28: N/D | I28: 3898 | J28: N/D | K28: N/D | L28: MANTOVARMI SNC DI BERGHAMASCHI FABIO & C | M28: 162 | O28: =+M28+N28 | R28: 120 | S28: 1 | T28: CA42796IR | U28: 45821 | V28: 12 | W28: 45821 | X28: PHILIPPOS COSTANTINIDES TRADING CO. LTD
A29: =+D29-S29 | C29: 45390 | D29: 1 | E29: FUCILE DOPPIETTA | F29: 12 | G29: CASTELLANI | H29: N/D | I29: 8479 | J29: N/D | K29: N/D | L29: MANTOVARMI SNC DI BERGHAMASCHI FABIO & C | M29: 162 | O29: =+M29+N29 | R29: 120 | S29: 1 | T29: CA42796IR | U29: 45821 | V29: 14 | W29: 45821 | X29: PHILIPPOS COSTANTINIDES TRADING CO. LTD
A30: =+D30-S30 | C30: 45390 | D30: 1 | E30: FUCILE DOPPIETTA | F30: 12 | G30: FONTANESI | H30: N/D | I30: 6820 | J30: N/D | K30: N/D | L30: MANTOVARMI SNC DI BERGHAMASCHI FABIO & C | M30: 112 | O30: =+M30+N30 | R30: 92 | S30: 1 | T30: CA42796IR | U30: 45821 | V30: 13 | W30: 45821 | X30: PHILIPPOS COSTANTINIDES TRADING CO. LTD
A31: =+D31-S31 | C31: 45390 | D31: 1 | E31: FUCILE DOPPIETTA | F31: 12 | G31: GUERINI | H31: N/D | I31: 926 | J31: N/D | K31: N/D | L31: MANTOVARMI SNC DI BERGHAMASCHI FABIO & C | M31: 162 | O31: =+M31+N31 | R31: 100 | S31: 1 | T31: CA42796IR | U31: 45821 | V31: 14 | W31: 45821 | X31: PHILIPPOS COSTANTINIDES TRADING CO. LTD
A32: =+D32-S32 | C32: 45390 | D32: 1 | E32: FUCILE DOPPIETTA | F32: 20 | G32: FERUNION | H32: N/D | I32: G2122 | J32: N/D | K32: N/D | L32: MANTOVARMI SNC DI BERGHAMASCHI FABIO & C | M32: 112 | O32: =+M32+N32 | R32: 100 | S32: 1 | T32: CA42796IR | U32: 45821 | V32: 14 | W32: 45821 | X32: PHILIPPOS COSTANTINIDES TRADING CO. LTD
A33: =+D33-S33 | C33: 45390 | D33: 1 | E33: FUCILE DOPPIETTA | F33: 12 | G33: FANTINELLI | H33: N/D | I33: 10078F-7117 | J33: N/D | K33: N/D | L33: MANTOVARMI SNC DI BERGHAMASCHI FABIO & C | M33: 162 | O33: =+M33+N33 | R33: 120 | S33: 1 | T33: CA42796IR | U33: 45821 | V33: 15 | W33: 45821 | X33: PHILIPPOS COSTANTINIDES TRADING CO. LTD
A34: =+D34-S34 | C34: 45390 | D34: 1 | E34: FUCILE DOPPIETTA | F34: 12 | G34: BRUNELLI | H34: N/D | I34: 520 | J34: N/D | K34: N/D | L34: MANTOVARMI SNC DI BERGHAMASCHI FABIO & C | M34: 112 | O34: =+M34+N34 | R34: 100 | S34: 1 | T34: CA42796IR | U34: 45821 | V34: 12 | W34: 45821 | X34: PHILIPPOS COSTANTINIDES TRADING CO. LTD
A35: =+D35-S35 | C35: 45390 | D35: 1 | E35: FUCILE DOPPIETTA | F35: 16 | G35: MAROCCHI | H35: N/D | I35: 143427 | J35: N/D | K35: N/D | L35: MANTOVARMI SNC DI BERGHAMASCHI FABIO & C | M35: 112 | O35: =+M35+N35 | R35: 100 | S35: 1 | T35: CA42796IR | U35: 45821 | V35: 14 | W35: 45821 | X35: PHILIPPOS COSTANTINIDES TRADING CO. LTD
A36: =+D36-S36 | C36: 45390 | D36: 1 | E36: FUCILE DOPPIETTA | F36: 12 | G36: LANCELLOTTI | H36: N/D | I36: 5808 | J36: N/D | K36: N/D | L36: MANTOVARMI SNC DI BERGHAMASCHI FABIO & C | M36: 162 | O36: =+M36+N36 | R36: 92 | S36: 1 | T36: CA42796IR | U36: 45821 | V36: 14 | W36: 45821 | X36: PHILIPPOS COSTANTINIDES TRADING CO. LTD
A37: =+D37-S37 | C37: 45390 | D37: 1 | E37: FUCILE DOPPIETTA | F37: 12 | G37: ARTIGIANALE | H37: N/D | I37: 530 | J37: N/D | K37: N/D | L37: MANTOVARMI SNC DI BERGHAMASCHI FABIO & C | M37: 112 | O37: =+M37+N37 | R37: 100 | S37: 1 | T37: CA42796IR | U37: 45821 | V37: 12 | W37: 45821 | X37: PHILIPPOS COSTANTINIDES TRADING CO. LTD
A38: =+D38-S38 | C38: 45390 | D38: 1 | E38: FUCILE DOPPIETTA | F38: 12 | G38: BERNARDELLI | H38: N/D | I38: 734 | J38: N/D | K38: N/D | L38: MANTOVARMI SNC DI BERGHAMASCHI FABIO & C | M38: 112 | O38: =+M38+N38 | R38: 67 | S38: 1 | T38: CA42796IR | U38: 45821 | V38: 13 | W38: 45821 | X38: PHILIPPOS COSTANTINIDES TRADING CO. LTD
A39: =+D39-S39 | C39: 45390 | D39: 1 | E39: FUCILE DOPPIETTA | F39: 12 | G39: SENZAMARCA | H39: N/D | I39: 34D | J39: N/D | K39: N/D | L39: MANTOVARMI SNC DI BERGHAMASCHI FABIO & C | M39: 112 | O39: =+M39+N39 | R39: 67 | S39: 1 | T39: CA42796IR | U39: 45821 | V39: 12 | W39: 45821 | X39: PHILIPPOS COSTANTINIDES TRADING CO. LTD
A40: =+D40-S40 | C40: 45390 | D40: 1 | E40: FUCILE DOPPIETTA | F40: 16 | G40: DAMAS | H40: N/D | I40: 307470 | J40: N/D | K40: N/D | L40: MANTOVARMI SNC DI BERGHAMASCHI FABIO & C | M40: 112 | O40: =+M40+N40 | R40: 67 | S40: 1 | T40: CA42796IR | U40: 45821 | V40: 14 | W40: 45821 | X40: PHILIPPOS COSTANTINIDES TRADING CO. LTD
...

Sheet REGISTRO
A1: CARICO | N1: SCARICO
A2: N. OPERAZIONE | B2: DATA | C2: N. ARMI | D2: ARMA | K2: FABBRICANTE O VENDITORE | L2: PREZZO | M2: NOTE | N2: DATA | O2: ACQUIRENTE | P2: TITOLO DI ACQUISTO
D3: TIPOLOGIA | E3: CALIBRO | F3: MARCA | G3: MODELLO | H3: MATR. ARMA | I3: MATR. CANNA | J3: MATR. AGG. | L3: €
A4: 2334 | B4: =+VLOOKUP($A4,MAGAZZINO!$B$2:$M$100000,2,FALSE) | C4: =+VLOOKUP($A4,MAGAZZINO!$B$2:$M$100000,3,FALSE) | D4: =+VLOOKUP($A4,MAGAZZINO!$B$2:$M$100000,4,FALSE) | E4: =+VLOOKUP($A4,MAGAZZINO!$B$2:$M$100000,5,FALSE) | F4: =+VLOOKUP($A4,MAGAZZINO!$B$2:$M$100000,6,FALSE) | G4: =+VLOOKUP($A4,MAGAZZINO!$B$2:$M$100000,7,FALSE) | H4: =+VLOOKUP($A4,MAGAZZINO!$B$2:$M$100000,8,FALSE) | I4: =+VLOOKUP($A4,MAGAZZINO!$B$2:$M$100000,9,FALSE) | J4: =+VLOOKUP($A4,MAGAZZINO!$B$2:$M$100000,10,FALSE) | K4: =+VLOOKUP($A4,MAGAZZINO!$B$2:$M$100000,11,FALSE) | L4: =+VLOOKUP($A4,MAGAZZINO!$B$2:$M$100000,12,FALSE) | N4: 45609 | O4: HS & LLC (OMAN) | P4: IMPORT LICENSE N. 24/1/2463/1/2024 DEL 05/05/2024 AUT. ESPORTAZIONE MULTIPLA N. 6B/2024/2M RILASCIATA IL 30/07/2024 (LICENZA DI SCARICO N. 6B/2024/1S RILASCIATA IL 06/11/2024)
A5: 2335 | B5: =+VLOOKUP($A5,MAGAZZINO!$B$2:$M$100000,2,FALSE) | C5: =+VLOOKUP($A5,MAGAZZINO!$B$2:$M$100000,3,FALSE) | D5: =+VLOOKUP($A5,MAGAZZINO!$B$2:$M$100000,4,FALSE) | E5: =+VLOOKUP($A5,MAGAZZINO!$B$2:$M$100000,5,FALSE) | F5: =+VLOOKUP($A5,MAGAZZINO!$B$2:$M$100000,6,FALSE) | G5: =+VLOOKUP($A5,MAGAZZINO!$B$2:$M$100000,7,FALSE) | H5: =+VLOOKUP($A5,MAGAZZINO!$B$2:$M$100000,8,FALSE) | I5: =+VLOOKUP($A5,MAGAZZINO!$B$2:$M$100000,9,FALSE) | J5: =+VLOOKUP($A5,MAGAZZINO!$B$2:$M$100000,10,FALSE) | K5: =+VLOOKUP($A5,MAGAZZINO!$B$2:$M$100000,11,FALSE) | L5: =+VLOOKUP($A5,MAGAZZINO!$B$2:$M$100000,12,FALSE) | N5: 45609 | O5: HS & LLC (OMAN) | P5: IMPORT LICENSE N. 24/1/2463/1/2024 DEL 05/05/2024 AUT. ESPORTAZIONE MULTIPLA N. 6B/2024/2M RILASCIATA IL 30/07/2024 (LICENZA DI SCARICO N. 6B/2024/1S RILASCIATA IL 06/11/2024)
A6: 2336 | B6: =+VLOOKUP($A6,MAGAZZINO!$B$2:$M$100000,2,FALSE) | C6: =+VLOOKUP($A6,MAGAZZINO!$B$2:$M$100000,3,FALSE) | D6: =+VLOOKUP($A6,MAGAZZINO!$B$2:$M$100000,4,FALSE) | E6: =+VLOOKUP($A6,MAGAZZINO!$B$2:$M$100000,5,FALSE) | F6: =+VLOOKUP($A6,MAGAZZINO!$B$2:$M$100000,6,FALSE) | G6: =+VLOOKUP($A6,MAGAZZINO!$B$2:$M$100000,7,FALSE) | H6: =+VLOOKUP($A6,MAGAZZINO!$B$2:$M$100000,8,FALSE) | I6: =+VLOOKUP($A6,MAGAZZINO!$B$2:$M$100000,9,FALSE) | J6: =+VLOOKUP($A6,MAGAZZINO!$B$2:$M$100000,10,FALSE) | K6: =+VLOOKUP($A6,MAGAZZINO!$B$2:$M$100000,11,FALSE) | L6: =+VLOOKUP($A6,MAGAZZINO!$B$2:$M$100000,12,FALSE) | N6: 45609 | O6: HS & LLC (OMAN) | P6: IMPORT LICENSE N. 24/1/2463/1/2024 DEL 05/05/2024 AUT. ESPORTAZIONE MULTIPLA N. 6B/2024/2M RILASCIATA IL 30/07/2024 (LICENZA DI SCARICO N. 6B/2024/1S RILASCIATA IL 06/11/2024)
A7: 2337 | B7: =+VLOOKUP($A7,MAGAZZINO!$B$2:$M$100000,2,FALSE) | C7: =+VLOOKUP($A7,MAGAZZINO!$B$2:$M$100000,3,FALSE) | D7: =+VLOOKUP($A7,MAGAZZINO!$B$2:$M$100000,4,FALSE) | E7: =+VLOOKUP($A7,MAGAZZINO!$B$2:$M$100000,5,FALSE) | F7: =+VLOOKUP($A7,MAGAZZINO!$B$2:$M$100000,6,FALSE) | G7: =+VLOOKUP($A7,MAGAZZINO!$B$2:$M$100000,7,FALSE) | H7: =+VLOOKUP($A7,MAGAZZINO!$B$2:$M$100000,8,FALSE) | I7: =+VLOOKUP($A7,MAGAZZINO!$B$2:$M$100000,9,FALSE) | J7: =+VLOOKUP($A7,MAGAZZINO!$B$2:$M$100000,10,FALSE) | K7: =+VLOOKUP($A7,MAGAZZINO!$B$2:$M$100000,11,FALSE) | L7: =+VLOOKUP($A7,MAGAZZINO!$B$2:$M$100000,12,FALSE) | N7: 45609 | O7: HS & LLC (OMAN) | P7: IMPORT LICENSE N. 24/1/2463/1/2024 DEL 05/05/2024 AUT. ESPORTAZIONE MULTIPLA N. 6B/2024/2M RILASCIATA IL 30/07/2024 (LICENZA DI SCARICO N. 6B/2024/1S RILASCIATA IL 06/11/2024)
A8: 2338 | B8: =+VLOOKUP($A8,MAGAZZINO!$B$2:$M$100000,2,FALSE) | C8: =+VLOOKUP($A8,MAGAZZINO!$B$2:$M$100000,3,FALSE) | D8: =+VLOOKUP($A8,MAGAZZINO!$B$2:$M$100000,4,FALSE) | E8: =+VLOOKUP($A8,MAGAZZINO!$B$2:$M$100000,5,FALSE) | F8: =+VLOOKUP($A8,MAGAZZINO!$B$2:$M$100000,6,FALSE) | G8: =+VLOOKUP($A8,MAGAZZINO!$B$2:$M$100000,7,FALSE) | H8: =+VLOOKUP($A8,MAGAZZINO!$B$2:$M$100000,8,FALSE) | I8: =+VLOOKUP($A8,MAGAZZINO!$B$2:$M$100000,9,FALSE) | J8: =+VLOOKUP($A8,MAGAZZINO!$B$2:$M$100000,10,FALSE) | K8: =+VLOOKUP($A8,MAGAZZINO!$B$2:$M$100000,11,FALSE) | L8: =+VLOOKUP($A8,MAGAZZINO!$B$2:$M$100000,12,FALSE) | N8: 45609 | O8: HS & LLC (OMAN) | P8: IMPORT LICENSE N. 24/1/2463/1/2024 DEL 05/05/2024 AUT. ESPORTAZIONE MULTIPLA N. 6B/2024/2M RILASCIATA IL 30/07/2024 (LICENZA DI SCARICO N. 6B/2024/1S RILASCIATA IL 06/11/2024)
A9: 2339 | B9: =+VLOOKUP($A9,MAGAZZINO!$B$2:$M$100000,2,FALSE) | C9: =+VLOOKUP($A9,MAGAZZINO!$B$2:$M$100000,3,FALSE) | D9: =+VLOOKUP($A9,MAGAZZINO!$B$2:$M$100000,4,FALSE) | E9: =+VLOOKUP($A9,MAGAZZINO!$B$2:$M$100000,5,FALSE) | F9: =+VLOOKUP($A9,MAGAZZINO!$B$2:$M$100000,6,FALSE) | G9: =+VLOOKUP($A9,MAGAZZINO!$B$2:$M$100000,7,FALSE) | H9: =+VLOOKUP($A9,MAGAZZINO!$B$2:$M$100000,8,FALSE) | I9: =+VLOOKUP($A9,MAGAZZINO!$B$2:$M$100000,9,FALSE) | J9: =+VLOOKUP($A9,MAGAZZINO!$B$2:$M$100000,10,FALSE) | K9: =+VLOOKUP($A9,MAGAZZINO!$B$2:$M$100000,11,FALSE) | L9: =+VLOOKUP($A9,MAGAZZINO!$B$2:$M$100000,12,FALSE) | N9: 45609 | O9: HS & LLC (OMAN) | P9: IMPORT LICENSE N. 24/1/2463/1/2024 DEL 05/05/2024 AUT. ESPORTAZIONE MULTIPLA N. 6B/2024/2M RILASCIATA IL 30/07/2024 (LICENZA DI SCARICO N. 6B/2024/1S RILASCIATA IL 06/11/2024)
A10: 2340 | B10: =+VLOOKUP($A10,MAGAZZINO!$B$2:$M$100000,2,FALSE) | C10: =+VLOOKUP($A10,MAGAZZINO!$B$2:$M$100000,3,FALSE) | D10: =+VLOOKUP($A10,MAGAZZINO!$B$2:$M$100000,4,FALSE) | E10: =+VLOOKUP($A10,MAGAZZINO!$B$2:$M$100000,5,FALSE) | F10: =+VLOOKUP($A10,MAGAZZINO!$B$2:$M$100000,6,FALSE) | G10: =+VLOOKUP($A10,MAGAZZINO!$B$2:$M$100000,7,FALSE) | H10: =+VLOOKUP($A10,MAGAZZINO!$B$2:$M$100000,8,FALSE) | I10: =+VLOOKUP($A10,MAGAZZINO!$B$2:$M$100000,9,FALSE) | J10: =+VLOOKUP($A10,MAGAZZINO!$B$2:$M$100000,10,FALSE) | K10: =+VLOOKUP($A10,MAGAZZINO!$B$2:$M$100000,11,FALSE) | L10: =+VLOOKUP($A10,MAGAZZINO!$B$2:$M$100000,12,FALSE) | N10: 45609 | O10: HS & LLC (OMAN) | P10: IMPORT LICENSE N. 24/1/2463/1/2024 DEL 05/05/2024 AUT. ESPORTAZIONE MULTIPLA N. 6B/2024/2M RILASCIATA IL 30/07/2024 (LICENZA DI SCARICO N. 6B/2024/1S RILASCIATA IL 06/11/2024)
A11: 2341 | B11: =+VLOOKUP($A11,MAGAZZINO!$B$2:$M$100000,2,FALSE) | C11: =+VLOOKUP($A11,MAGAZZINO!$B$2:$M$100000,3,FALSE) | D11: =+VLOOKUP($A11,MAGAZZINO!$B$2:$M$100000,4,FALSE) | E11: =+VLOOKUP($A11,MAGAZZINO!$B$2:$M$100000,5,FALSE) | F11: =+VLOOKUP($A11,MAGAZZINO!$B$2:$M$100000,6,FALSE) | G11: =+VLOOKUP($A11,MAGAZZINO!$B$2:$M$100000,7,FALSE) | H11: =+VLOOKUP($A11,MAGAZZINO!$B$2:$M$100000,8,FALSE) | I11: =+VLOOKUP($A11,MAGAZZINO!$B$2:$M$100000,9,FALSE) | J11: =+VLOOKUP($A11,MAGAZZINO!$B$2:$M$100000,10,FALSE) | K11: =+VLOOKUP($A11,MAGAZZINO!$B$2:$M$100000,11,FALSE) | L11: =+VLOOKUP($A11,MAGAZZINO!$B$2:$M$100000,12,FALSE) | N11: 45609 | O11: HS & LLC (OMAN) | P11: IMPORT LICENSE N. 24/1/2463/1/2024 DEL 05/05/2024 AUT. ESPORTAZIONE MULTIPLA N. 6B/2024/2M RILASCIATA IL 30/07/2024 (LICENZA DI SCARICO N. 6B/2024/1S RILASCIATA IL 06/11/2024)
A12: 2342 | B12: =+VLOOKUP($A12,MAGAZZINO!$B$2:$M$100000,2,FALSE) | C12: =+VLOOKUP($A12,MAGAZZINO!$B$2:$M$100000,3,FALSE) | D12: =+VLOOKUP($A12,MAGAZZINO!$B$2:$M$100000,4,FALSE) | E12: =+VLOOKUP($A12,MAGAZZINO!$B$2:$M$100000,5,FALSE) | F12: =+VLOOKUP($A12,MAGAZZINO!$B$2:$M$100000,6,FALSE) | G12: =+VLOOKUP($A12,MAGAZZINO!$B$2:$M$100000,7,FALSE) | H12: =+VLOOKUP($A12,MAGAZZINO!$B$2:$M$100000,8,FALSE) | I12: =+VLOOKUP($A12,MAGAZZINO!$B$2:$M$100000,9,FALSE) | J12: =+VLOOKUP($A12,MAGAZZINO!$B$2:$M$100000,10,FALSE) | K12: =+VLOOKUP($A12,MAGAZZINO!$B$2:$M$100000,11,FALSE) | L12: =+VLOOKUP($A12,MAGAZZINO!$B$2:$M$100000,12,FALSE) | N12: 45609 | O12: HS & LLC (OMAN) | P12: IMPORT LICENSE N. 24/1/2463/1/2024 DEL 05/05/2024 AUT. ESPORTAZIONE MULTIPLA N. 6B/2024/2M RILASCIATA IL 30/07/2024 (LICENZA DI SCARICO N. 6B/2024/1S RILASCIATA IL 06/11/2024)
A13: 2343 | B13: =+VLOOKUP($A13,MAGAZZINO!$B$2:$M$100000,2,FALSE) | C13: =+VLOOKUP($A13,MAGAZZINO!$B$2:$M$100000,3,FALSE) | D13: =+VLOOKUP($A13,MAGAZZINO!$B$2:$M$100000,4,FALSE) | E13: =+VLOOKUP($A13,MAGAZZINO!$B$2:$M$100000,5,FALSE) | F13: =+VLOOKUP($A13,MAGAZZINO!$B$2:$M$100000,6,FALSE) | G13: =+VLOOKUP($A13,MAGAZZINO!$B$2:$M$100000,7,FALSE) | H13: =+VLOOKUP($A13,MAGAZZINO!$B$2:$M$100000,8,FALSE) | I13: =+VLOOKUP($A13,MAGAZZINO!$B$2:$M$100000,9,FALSE) | J13: =+VLOOKUP($A13,MAGAZZINO!$B$2:$M$100000,10,FALSE) | K13: =+VLOOKUP($A13,MAGAZZINO!$B$2:$M$100000,11,FALSE) | L13: =+VLOOKUP($A13,MAGAZZINO!$B$2:$M$100000,12,FALSE) | N13: 45609 | O13: HS & LLC (OMAN) | P13: IMPORT LICENSE N. 24/1/2463/1/2024 DEL 05/05/2024 AUT. ESPORTAZIONE MULTIPLA N. 6B/2024/2M RILASCIATA IL 30/07/2024 (LICENZA DI SCARICO N. 6B/2024/1S RILASCIATA IL 06/11/2024)
A14: 2344 | B14: =+VLOOKUP($A14,MAGAZZINO!$B$2:$M$100000,2,FALSE) | C14: =+VLOOKUP($A14,MAGAZZINO!$B$2:$M$100000,3,FALSE) | D14: =+VLOOKUP($A14,MAGAZZINO!$B$2:$M$100000,4,FALSE) | E14: =+VLOOKUP($A14,MAGAZZINO!$B$2:$M$100000,5,FALSE) | F14: =+VLOOKUP($A14,MAGAZZINO!$B$2:$M$100000,6,FALSE) | G14: =+VLOOKUP($A14,MAGAZZINO!$B$2:$M$100000,7,FALSE) | H14: =+VLOOKUP($A14,MAGAZZINO!$B$2:$M$100000,8,FALSE) | I14: =+VLOOKUP($A14,MAGAZZINO!$B$2:$M$100000,9,FALSE) | J14: =+VLOOKUP($A14,MAGAZZINO!$B$2:$M$100000,10,FALSE) | K14: =+VLOOKUP($A14,MAGAZZINO!$B$2:$M$100000,11,FALSE) | L14: =+VLOOKUP($A14,MAGAZZINO!$B$2:$M$100000,12,FALSE) | N14: 45609 | O14: HS & LLC (OMAN) | P14: IMPORT LICENSE N. 24/1/2463/1/2024 DEL 05/05/2024 AUT. ESPORTAZIONE MULTIPLA N. 6B/2024/2M RILASCIATA IL 30/07/2024 (LICENZA DI SCARICO N. 6B/2024/1S RILASCIATA IL 06/11/2024)
A15: 2345 | B15: =+VLOOKUP($A15,MAGAZZINO!$B$2:$M$100000,2,FALSE) | C15: =+VLOOKUP($A15,MAGAZZINO!$B$2:$M$100000,3,FALSE) | D15: =+VLOOKUP($A15,MAGAZZINO!$B$2:$M$100000,4,FALSE) | E15: =+VLOOKUP($A15,MAGAZZINO!$B$2:$M$100000,5,FALSE) | F15: =+VLOOKUP($A15,MAGAZZINO!$B$2:$M$100000,6,FALSE) | G15: =+VLOOKUP($A15,MAGAZZINO!$B$2:$M$100000,7,FALSE) | H15: =+VLOOKUP($A15,MAGAZZINO!$B$2:$M$100000,8,FALSE) | I15: =+VLOOKUP($A15,MAGAZZINO!$B$2:$M$100000,9,FALSE) | J15: =+VLOOKUP($A15,MAGAZZINO!$B$2:$M$100000,10,FALSE) | K15: =+VLOOKUP($A15,MAGAZZINO!$B$2:$M$100000,11,FALSE) | L15: =+VLOOKUP($A15,MAGAZZINO!$B$2:$M$100000,12,FALSE) | N15: 45609 | O15: HS & LLC (OMAN) | P15: IMPORT LICENSE N. 24/1/2463/1/2024 DEL 05/05/2024 AUT. ESPORTAZIONE MULTIPLA N. 6B/2024/2M RILASCIATA IL 30/07/2024 (LICENZA DI SCARICO N. 6B/2024/1S RILASCIATA IL 06/11/2024)
A16: 2346 | B16: =+VLOOKUP($A16,MAGAZZINO!$B$2:$M$100000,2,FALSE) | C16: =+VLOOKUP($A16,MAGAZZINO!$B$2:$M$100000,3,FALSE) | D16: =+VLOOKUP($A16,MAGAZZINO!$B$2:$M$100000,4,FALSE) | E16: =+VLOOKUP($A16,MAGAZZINO!$B$2:$M$100000,5,FALSE) | F16: =+VLOOKUP($A16,MAGAZZINO!$B$2:$M$100000,6,FALSE) | G16: =+VLOOKUP($A16,MAGAZZINO!$B$2:$M$100000,7,FALSE) | H16: =+VLOOKUP($A16,MAGAZZINO!$B$2:$M$100000,8,FALSE) | I16: =+VLOOKUP($A16,MAGAZZINO!$B$2:$M$100000,9,FALSE) | J16: =+VLOOKUP($A16,MAGAZZINO!$B$2:$M$100000,10,FALSE) | K16: =+VLOOKUP($A16,MAGAZZINO!$B$2:$M$100000,11,FALSE) | L16: =+VLOOKUP($A16,MAGAZZINO!$B$2:$M$100000,12,FALSE) | N16: 45609 | O16: HS & LLC (OMAN) | P16: IMPORT LICENSE N. 24/1/2463/1/2024 DEL 05/05/2024 AUT. ESPORTAZIONE MULTIPLA N. 6B/2024/2M RILASCIATA IL 30/07/2024 (LICENZA DI SCARICO N. 6B/2024/1S RILASCIATA IL 06/11/2024)
A17: 2347 | B17: =+VLOOKUP($A17,MAGAZZINO!$B$2:$M$100000,2,FALSE) | C17: =+VLOOKUP($A17,MAGAZZINO!$B$2:$M$100000,3,FALSE) | D17: =+VLOOKUP($A17,MAGAZZINO!$B$2:$M$100000,4,FALSE) | E17: =+VLOOKUP($A17,MAGAZZINO!$B$2:$M$100000,5,FALSE) | F17: =+VLOOKUP($A17,MAGAZZINO!$B$2:$M$100000,6,FALSE) | G17: =+VLOOKUP($A17,MAGAZZINO!$B$2:$M$100000,7,FALSE) | H17: =+VLOOKUP($A17,MAGAZZINO!$B$2:$M$100000,8,FALSE) | I17: =+VLOOKUP($A17,MAGAZZINO!$B$2:$M$100000,9,FALSE) | J17: =+VLOOKUP($A17,MAGAZZINO!$B$2:$M$100000,10,FALSE) | K17: =+VLOOKUP($A17,MAGAZZINO!$B$2:$M$100000,11,FALSE) | L17: =+VLOOKUP($A17,MAGAZZINO!$B$2:$M$100000,12,FALSE) | N17: 08/11/2024 12/11/2024 13/11/2024 | O17: BRUGAR SRL MARCHENO (BS) B.C.W. SRL RIPRESO IN CARICO HS & LLC (OMAN) | P17: D.D.T. N. 15 DEL 08/11/2024 ATA N. 10 DEL 05/11/2024 D.D.T. N. 2024-1820/M RIPRESO IN CARICO ATA N. 6C-P06012400011801 DEL 08/11/2024 IMPORT LICENSE N. 24/1/2463/1/2024 DEL 05/05/2024 AUT. ESPORTAZIONE MULTIPLA N. 6B/2024/2M RILASCIATA IL 30/07/2024 (LICENZA DI SCARICO N. 6B/2024/1S RILASCIATA IL N. /11/2024)
A18: 2348 | B18: =+VLOOKUP($A18,MAGAZZINO!$B$2:$M$100000,2,FALSE) | C18: =+VLOOKUP($A18,MAGAZZINO!$B$2:$M$100000,3,FALSE) | D18: =+VLOOKUP($A18,MAGAZZINO!$B$2:$M$100000,4,FALSE) | E18: =+VLOOKUP($A18,MAGAZZINO!$B$2:$M$100000,5,FALSE) | F18: =+VLOOKUP($A18,MAGAZZINO!$B$2:$M$100000,6,FALSE) | G18: =+VLOOKUP($A18,MAGAZZINO!$B$2:$M$100000,7,FALSE) | H18: =+VLOOKUP($A18,MAGAZZINO!$B$2:$M$100000,8,FALSE) | I18: =+VLOOKUP($A18,MAGAZZINO!$B$2:$M$100000,9,FALSE) | J18: =+VLOOKUP($A18,MAGAZZINO!$B$2:$M$100000,10,FALSE) | K18: =+VLOOKUP($A18,MAGAZZINO!$B$2:$M$100000,11,FALSE) | L18: =+VLOOKUP($A18,MAGAZZINO!$B$2:$M$100000,12,FALSE) | N18: 08/11/2024 12/11/2024 13/11/2024 | O18: BRUGAR SRL MARCHENO (BS) B.C.W. SRL RIPRESO IN CARICO HS & LLC (OMAN) | P18: D.D.T. N. 15 DEL 08/11/2024 ATA N. 10 DEL 05/11/2024 D.D.T. N. 2024-1820/M RIPRESO IN CARICO ATA N. 6C-P06012400011801 DEL 08/11/2024 IMPORT LICENSE N. 24/1/2463/1/2024 DEL 05/05/2024 AUT. ESPORTAZIONE MULTIPLA N. 6B/2024/2M RILASCIATA IL 30/07/2024 (LICENZA DI SCARICO N. 6B/2024/1S RILASCIATA IL N. /11/2024)
A19: 2349 | B19: =+VLOOKUP($A19,MAGAZZINO!$B$2:$M$100000,2,FALSE) | C19: =+VLOOKUP($A19,MAGAZZINO!$B$2:$M$100000,3,FALSE) | D19: =+VLOOKUP($A19,MAGAZZINO!$B$2:$M$100000,4,FALSE) | E19: =+VLOOKUP($A19,MAGAZZINO!$B$2:$M$100000,5,FALSE) | F19: =+VLOOKUP($A19,MAGAZZINO!$B$2:$M$100000,6,FALSE) | G19: =+VLOOKUP($A19,MAGAZZINO!$B$2:$M$100000,7,FALSE) | H19: =+VLOOKUP($A19,MAGAZZINO!$B$2:$M$100000,8,FALSE) | I19: =+VLOOKUP($A19,MAGAZZINO!$B$2:$M$100000,9,FALSE) | J19: =+VLOOKUP($A19,MAGAZZINO!$B$2:$M$100000,10,FALSE) | K19: =+VLOOKUP($A19,MAGAZZINO!$B$2:$M$100000,11,FALSE) | L19: =+VLOOKUP($A19,MAGAZZINO!$B$2:$M$100000,12,FALSE) | N19: 45609 | O19: HS & LLC (OMAN) | P19: IMPORT LICENSE N. 24/1/2463/1/2024 DEL 05/05/2024 AUT. ESPORTAZIONE MULTIPLA N. 6B/2024/2M RILASCIATA IL 30/07/2024 (LICENZA DI SCARICO N. 6B/2024/1S RILASCIATA IL 06/11/2024)
A20: 2350 | B20: =+VLOOKUP($A20,MAGAZZINO!$B$2:$M$100000,2,FALSE) | C20: =+VLOOKUP($A20,MAGAZZINO!$B$2:$M$100000,3,FALSE) | D20: =+VLOOKUP($A20,MAGAZZINO!$B$2:$M$100000,4,FALSE) | E20: =+VLOOKUP($A20,MAGAZZINO!$B$2:$M$100000,5,FALSE) | F20: =+VLOOKUP($A20,MAGAZZINO!$B$2:$M$100000,6,FALSE) | G20: =+VLOOKUP($A20,MAGAZZINO!$B$2:$M$100000,7,FALSE) | H20: =+VLOOKUP($A20,MAGAZZINO!$B$2:$M$100000,8,FALSE) | I20: =+VLOOKUP($A20,MAGAZZINO!$B$2:$M$100000,9,FALSE) | J20: =+VLOOKUP($A20,MAGAZZINO!$B$2:$M$100000,10,FALSE) | K20: =+VLOOKUP($A20,MAGAZZINO!$B$2:$M$100000,11,FALSE) | L20: =+VLOOKUP($A20,MAGAZZINO!$B$2:$M$100000,12,FALSE) | N20: 45609 | O20: HS & LLC (OMAN) | P20: IMPORT LICENSE N. 24/1/2463/1/2024 DEL 05/05/2024 AUT. ESPORTAZIONE MULTIPLA N. 6B/2024/2M RILASCIATA IL 30/07/2024 (LICENZA DI SCARICO N. 6B/2024/1S RILASCIATA IL 06/11/2024)
A21: 2351 | B21: =+VLOOKUP($A21,MAGAZZINO!$B$2:$M$100000,2,FALSE) | C21: =+VLOOKUP($A21,MAGAZZINO!$B$2:$M$100000,3,FALSE) | D21: =+VLOOKUP($A21,MAGAZZINO!$B$2:$M$100000,4,FALSE) | E21: =+VLOOKUP($A21,MAGAZZINO!$B$2:$M$100000,5,FALSE) | F21: =+VLOOKUP($A21,MAGAZZINO!$B$2:$M$100000,6,FALSE) | G21: =+VLOOKUP($A21,MAGAZZINO!$B$2:$M$100000,7,FALSE) | H21: =+VLOOKUP($A21,MAGAZZINO!$B$2:$M$100000,8,FALSE) | I21: =+VLOOKUP($A21,MAGAZZINO!$B$2:$M$100000,9,FALSE) | J21: =+VLOOKUP($A21,MAGAZZINO!$B$2:$M$100000,10,FALSE) | K21: =+VLOOKUP($A21,MAGAZZINO!$B$2:$M$100000,11,FALSE) | L21: =+VLOOKUP($A21,MAGAZZINO!$B$2:$M$100000,12,FALSE) | N21: 45609 | O21: HS & LLC (OMAN) | P21: IMPORT LICENSE N. 24/1/2463/1/2024 DEL 05/05/2024 AUT. ESPORTAZIONE MULTIPLA N. 6B/2024/2M RILASCIATA IL 30/07/2024 (LICENZA DI SCARICO N. 6B/2024/1S RILASCIATA IL 06/11/2024)
A22: 2352 | B22: =+VLOOKUP($A22,MAGAZZINO!$B$2:$M$100000,2,FALSE) | C22: =+VLOOKUP($A22,MAGAZZINO!$B$2:$M$100000,3,FALSE) | D22: =+VLOOKUP($A22,MAGAZZINO!$B$2:$M$100000,4,FALSE) | E22: =+VLOOKUP($A22,MAGAZZINO!$B$2:$M$100000,5,FALSE) | F22: =+VLOOKUP($A22,MAGAZZINO!$B$2:$M$100000,6,FALSE) | G22: =+VLOOKUP($A22,MAGAZZINO!$B$2:$M$100000,7,FALSE) | H22: =+VLOOKUP($A22,MAGAZZINO!$B$2:$M$100000,8,FALSE) | I22: =+VLOOKUP($A22,MAGAZZINO!$B$2:$M$100000,9,FALSE) | J22: =+VLOOKUP($A22,MAGAZZINO!$B$2:$M$100000,10,FALSE) | K22: =+VLOOKUP($A22,MAGAZZINO!$B$2:$M$100000,11,FALSE) | L22: =+VLOOKUP($A22,MAGAZZINO!$B$2:$M$100000,12,FALSE) | N22: 45609 | O22: HS & LLC (OMAN) | P22: IMPORT LICENSE N. 24/1/2463/1/2024 DEL 05/05/2024 AUT. ESPORTAZIONE MULTIPLA N. 6B/2024/2M RILASCIATA IL 30/07/2024 (LICENZA DI SCARICO N. 6B/2024/1S RILASCIATA IL 06/11/2024)
A23: 2353 | B23: =+VLOOKUP($A23,MAGAZZINO!$B$2:$M$100000,2,FALSE) | C23: =+VLOOKUP($A23,MAGAZZINO!$B$2:$M$100000,3,FALSE) | D23: =+VLOOKUP($A23,MAGAZZINO!$B$2:$M$100000,4,FALSE) | E23: =+VLOOKUP($A23,MAGAZZINO!$B$2:$M$100000,5,FALSE) | F23: =+VLOOKUP($A23,MAGAZZINO!$B$2:$M$100000,6,FALSE) | G23: =+VLOOKUP($A23,MAGAZZINO!$B$2:$M$100000,7,FALSE) | H23: =+VLOOKUP($A23,MAGAZZINO!$B$2:$M$100000,8,FALSE) | I23: =+VLOOKUP($A23,MAGAZZINO!$B$2:$M$100000,9,FALSE) | J23: =+VLOOKUP($A23,MAGAZZINO!$B$2:$M$100000,10,FALSE) | K23: =+VLOOKUP($A23,MAGAZZINO!$B$2:$M$100000,11,FALSE) | L23: =+VLOOKUP($A23,MAGAZZINO!$B$2:$M$100000,12,FALSE) | N23: 45609 | O23: HS & LLC (OMAN) | P23: IMPORT LICENSE N. 24/1/2463/1/2024 DEL 05/05/2024 AUT. ESPORTAZIONE MULTIPLA N. 6B/2024/2M RILASCIATA IL 30/07/2024 (LICENZA DI SCARICO N. 6B/2024/1S RILASCIATA IL 06/11/2024)
A24: 2354 | B24: =+VLOOKUP($A24,MAGAZZINO!$B$2:$M$100000,2,FALSE) | C24: =+VLOOKUP($A24,MAGAZZINO!$B$2:$M$100000,3,FALSE) | D24: =+VLOOKUP($A24,MAGAZZINO!$B$2:$M$100000,4,FALSE) | E24: =+VLOOKUP($A24,MAGAZZINO!$B$2:$M$100000,5,FALSE) | F24: =+VLOOKUP($A24,MAGAZZINO!$B$2:$M$100000,6,FALSE) | G24: =+VLOOKUP($A24,MAGAZZINO!$B$2:$M$100000,7,FALSE) | H24: =+VLOOKUP($A24,MAGAZZINO!$B$2:$M$100000,8,FALSE) | I24: =+VLOOKUP($A24,MAGAZZINO!$B$2:$M$100000,9,FALSE) | J24: =+VLOOKUP($A24,MAGAZZINO!$B$2:$M$100000,10,FALSE) | K24: =+VLOOKUP($A24,MAGAZZINO!$B$2:$M$100000,11,FALSE) | L24: =+VLOOKUP($A24,MAGAZZINO!$B$2:$M$100000,12,FALSE) | N24: 45609 | O24: HS & LLC (OMAN) | P24: IMPORT LICENSE N. 24/1/2463/1/2024 DEL 05/05/2024 AUT. ESPORTAZIONE MULTIPLA N. 6B/2024/2M RILASCIATA IL 30/07/2024 (LICENZA DI SCARICO N. 6B/2024/1S RILASCIATA IL 06/11/2024)
A25: 2355 | B25: =+VLOOKUP($A25,MAGAZZINO!$B$2:$M$100000,2,FALSE) | C25: =+VLOOKUP($A25,MAGAZZINO!$B$2:$M$100000,3,FALSE) | D25: =+VLOOKUP($A25,MAGAZZINO!$B$2:$M$100000,4,FALSE) | E25: =+VLOOKUP($A25,MAGAZZINO!$B$2:$M$100000,5,FALSE) | F25: =+VLOOKUP($A25,MAGAZZINO!$B$2:$M$100000,6,FALSE) | G25: =+VLOOKUP($A25,MAGAZZINO!$B$2:$M$100000,7,FALSE) | H25: =+VLOOKUP($A25,MAGAZZINO!$B$2:$M$100000,8,FALSE) | I25: =+VLOOKUP($A25,MAGAZZINO!$B$2:$M$100000,9,FALSE) | J25: =+VLOOKUP($A25,MAGAZZINO!$B$2:$M$100000,10,FALSE) | K25: =+VLOOKUP($A25,MAGAZZINO!$B$2:$M$100000,11,FALSE) | L25: =+VLOOKUP($A25,MAGAZZINO!$B$2:$M$100000,12,FALSE) | N25: 45609 | O25: HS & LLC (OMAN) | P25: IMPORT LICENSE N. 24/1/2463/1/2024 DEL 05/05/2024 AUT. ESPORTAZIONE MULTIPLA N. 6B/2024/2M RILASCIATA IL 30/07/2024 (LICENZA DI SCARICO N. 6B/2024/1S RILASCIATA IL 06/11/2024)
A26: 2356 | B26: =+VLOOKUP($A26,MAGAZZINO!$B$2:$M$100000,2,FALSE) | C26: =+VLOOKUP($A26,MAGAZZINO!$B$2:$M$100000,3,FALSE) | D26: =+VLOOKUP($A26,MAGAZZINO!$B$2:$M$100000,4,FALSE) | E26: =+VLOOKUP($A26,MAGAZZINO!$B$2:$M$100000,5,FALSE) | F26: =+VLOOKUP($A26,MAGAZZINO!$B$2:$M$100000,6,FALSE) | G26: =+VLOOKUP($A26,MAGAZZINO!$B$2:$M$100000,7,FALSE) | H26: =+VLOOKUP($A26,MAGAZZINO!$B$2:$M$100000,8,FALSE) | I26: =+VLOOKUP($A26,MAGAZZINO!$B$2:$M$100000,9,FALSE) | J26: =+VLOOKUP($A26,MAGAZZINO!$B$2:$M$100000,10,FALSE) | K26: =+VLOOKUP($A26,MAGAZZINO!$B$2:$M$100000,11,FALSE) | L26: =+VLOOKUP($A26,MAGAZZINO!$B$2:$M$100000,12,FALSE) | N26: 45609 | O26: HS & LLC (OMAN) | P26: IMPORT LICENSE N. 24/1/2463/1/2024 DEL 05/05/2024 AUT. ESPORTAZIONE MULTIPLA N. 6B/2024/2M RILASCIATA IL 30/07/2024 (LICENZA DI SCARICO N. 6B/2024/1S RILASCIATA IL 06/11/2024)
A27: 2357 | B27: =+VLOOKUP($A27,MAGAZZINO!$B$2:$M$100000,2,FALSE) | C27: =+VLOOKUP($A27,MAGAZZINO!$B$2:$M$100000,3,FALSE) | D27: =+VLOOKUP($A27,MAGAZZINO!$B$2:$M$100000,4,FALSE) | E27: =+VLOOKUP($A27,MAGAZZINO!$B$2:$M$100000,5,FALSE) | F27: =+VLOOKUP($A27,MAGAZZINO!$B$2:$M$100000,6,FALSE) | G27: =+VLOOKUP($A27,MAGAZZINO!$B$2:$M$100000,7,FALSE) | H27: =+VLOOKUP($A27,MAGAZZINO!$B$2:$M$100000,8,FALSE) | I27: =+VLOOKUP($A27,MAGAZZINO!$B$2:$M$100000,9,FALSE) | J27: =+VLOOKUP($A27,MAGAZZINO!$B$2:$M$100000,10,FALSE) | K27: =+VLOOKUP($A27,MAGAZZINO!$B$2:$M$100000,11,FALSE) | L27: =+VLOOKUP($A27,MAGAZZINO!$B$2:$M$100000,12,FALSE) | N27: 45609 | O27: HS & LLC (OMAN) | P27: IMPORT LICENSE N. 24/1/2463/1/2024 DEL 05/05/2024 AUT. ESPORTAZIONE MULTIPLA N. 6B/2024/2M RILASCIATA IL 30/07/2024 (LICENZA DI SCARICO N. 6B/2024/1S RILASCIATA IL 06/11/2024)
A28: 2358 | B28: =+VLOOKUP($A28,MAGAZZINO!$B$2:$M$100000,2,FALSE) | C28: =+VLOOKUP($A28,MAGAZZINO!$B$2:$M$100000,3,FALSE) | D28: =+VLOOKUP($A28,MAGAZZINO!$B$2:$M$100000,4,FALSE) | E28: =+VLOOKUP($A28,MAGAZZINO!$B$2:$M$100000,5,FALSE) | F28: =+VLOOKUP($A28,MAGAZZINO!$B$2:$M$100000,6,FALSE) | G28: =+VLOOKUP($A28,MAGAZZINO!$B$2:$M$100000,7,FALSE) | H28: =+VLOOKUP($A28,MAGAZZINO!$B$2:$M$100000,8,FALSE) | I28: =+VLOOKUP($A28,MAGAZZINO!$B$2:$M$100000,9,FALSE) | J28: =+VLOOKUP($A28,MAGAZZINO!$B$2:$M$100000,10,FALSE) | K28: =+VLOOKUP($A28,MAGAZZINO!$B$2:$M$100000,11,FALSE) | L28: =+VLOOKUP($A28,MAGAZZINO!$B$2:$M$100000,12,FALSE) | N28: 45609 | O28: HS & LLC (OMAN) | P28: IMPORT LICENSE N. 24/1/2463/1/2024 DEL 05/05/2024 AUT. ESPORTAZIONE MULTIPLA N. 6B/2024/2M RILASCIATA IL 30/07/2024 (LICENZA DI SCARICO N. 6B/2024/1S RILASCIATA IL 06/11/2024)
A29: 2359 | B29: =+VLOOKUP($A29,MAGAZZINO!$B$2:$M$100000,2,FALSE) | C29: =+VLOOKUP($A29,MAGAZZINO!$B$2:$M$100000,3,FALSE) | D29: =+VLOOKUP($A29,MAGAZZINO!$B$2:$M$100000,4,FALSE) | E29: =+VLOOKUP($A29,MAGAZZINO!$B$2:$M$100000,5,FALSE) | F29: =+VLOOKUP($A29,MAGAZZINO!$B$2:$M$100000,6,FALSE) | G29: =+VLOOKUP($A29,MAGAZZINO!$B$2:$M$100000,7,FALSE) | H29: =+VLOOKUP($A29,MAGAZZINO!$B$2:$M$100000,8,FALSE) | I29: =+VLOOKUP($A29,MAGAZZINO!$B$2:$M$100000,9,FALSE) | J29: =+VLOOKUP($A29,MAGAZZINO!$B$2:$M$100000,10,FALSE) | K29: =+VLOOKUP($A29,MAGAZZINO!$B$2:$M$100000,11,FALSE) | L29: =+VLOOKUP($A29,MAGAZZINO!$B$2:$M$100000,12,FALSE) | N29: 45609 | O29: HS & LLC (OMAN) | P29: IMPORT LICENSE N. 24/1/2463/1/2024 DEL 05/05/2024 AUT. ESPORTAZIONE MULTIPLA N. 6B/2024/2M RILASCIATA IL 30/07/2024 (LICENZA DI SCARICO N. 6B/2024/1S RILASCIATA IL 06/11/2024)
A30: 2360 | B30: =+VLOOKUP($A30,MAGAZZINO!$B$2:$M$100000,2,FALSE) | C30: =+VLOOKUP($A30,MAGAZZINO!$B$2:$M$100000,3,FALSE) | D30: =+VLOOKUP($A30,MAGAZZINO!$B$2:$M$100000,4,FALSE) | E30: =+VLOOKUP($A30,MAGAZZINO!$B$2:$M$100000,5,FALSE) | F30: =+VLOOKUP($A30,MAGAZZINO!$B$2:$M$100000,6,FALSE) | G30: =+VLOOKUP($A30,MAGAZZINO!$B$2:$M$100000,7,FALSE) | H30: =+VLOOKUP($A30,MAGAZZINO!$B$2:$M$100000,8,FALSE) | I30: =+VLOOKUP($A30,MAGAZZINO!$B$2:$M$100000,9,FALSE) | J30: =+VLOOKUP($A30,MAGAZZINO!$B$2:$M$100000,10,FALSE) | K30: =+VLOOKUP($A30,MAGAZZINO!$B$2:$M$100000,11,FALSE) | L30: =+VLOOKUP($A30,MAGAZZINO!$B$2:$M$100000,12,FALSE) | N30: 45609 | O30: HS & LLC (OMAN) | P30: IMPORT LICENSE N. 24/1/2463/1/2024 DEL 05/05/2024 AUT. ESPORTAZIONE MULTIPLA N. 6B/2024/2M RILASCIATA IL 30/07/2024 (LICENZA DI SCARICO N. 6B/2024/1S RILASCIATA IL 06/11/2024)
... A113: 2443 | B113: =+VLOOKUP($A113,MAGAZZINO!$B$2:$M$100000,2,FALSE) | C113: =+VLOOKUP($A113,MAGAZZINO!$B$2:$M$100000,3,FALSE) | D113: =+VLOOKUP($A113,MAGAZZINO!$B$2:$M$100000,4,FALSE) | E113: =+VLOOKUP($A113,MAGAZZINO!$B$2:$M$100000,5,FALSE) | F113: =+VLOOKUP($A113,MAGAZZINO!$B$2:$M$100000,6,FALSE) | G113: =+VLOOKUP($A113,MAGAZZINO!$B$2:$M$100000,7,FALSE) | H113: =+VLOOKUP($A113,MAGAZZINO!$B$2:$M$100000,8,FALSE) | I113: =+VLOOKUP($A113,MAGAZZINO!$B$2:$M$100000,9,FALSE) | J113: =+VLOOKUP($A113,MAGAZZINO!$B$2:$M$100000,10,FALSE) | K113: =+VLOOKUP($A113,MAGAZZINO!$B$2:$M$100000,11,FALSE) | L113: =+VLOOKUP($A113,MAGAZZINO!$B$2:$M$100000,12,FALSE) | N113: 45609 | O113: HS & LLC (OMAN) | P113: IMPORT LICENSE N. 24/1/2463/1/2024 DEL 05/05/2024 AUT. ESPORTAZIONE MULTIPLA N. 6B/2024/2M RILASCIATA IL 30/07/2024 (LICENZA DI SCARICO N. 6B/2024/1S RILASCIATA IL 06/11/2024)
A114: 2444 | B114: =+VLOOKUP($A114,MAGAZZINO!$B$2:$M$100000,2,FALSE) | C114: =+VLOOKUP($A114,MAGAZZINO!$B$2:$M$100000,3,FALSE) | D114: =+VLOOKUP($A114,MAGAZZINO!$B$2:$M$100000,4,FALSE) | E114: =+VLOOKUP($A114,MAGAZZINO!$B$2:$M$100000,5,FALSE) | F114: =+VLOOKUP($A114,MAGAZZINO!$B$2:$M$100000,6,FALSE) | G114: =+VLOOKUP($A114,MAGAZZINO!$B$2:$M$100000,7,FALSE) | H114: =+VLOOKUP($A114,MAGAZZINO!$B$2:$M$100000,8,FALSE) | I114: =+VLOOKUP($A114,MAGAZZINO!$B$2:$M$100000,9,FALSE) | J114: =+VLOOKUP($A114,MAGAZZINO!$B$2:$M$100000,10,FALSE) | K114: =+VLOOKUP($A114,MAGAZZINO!$B$2:$M$100000,11,FALSE) | L114: =+VLOOKUP($A114,MAGAZZINO!$B$2:$M$100000,12,FALSE) | N114: 08/11/2024 12/11/2024 13/11/2024 | O114: BRUGAR SRL MARCHENO (BS) B.C.W. SRL RIPRESO IN CARICO HS & LLC (OMAN) | P114: D.D.T. N. 15 DEL 08/11/2024 ATA N. 10 DEL 05/11/2024 D.D.T. N. 2024-1820/M RIPRESO IN CARICO ATA N. 6C-P06012400011801 DEL 08/11/2024 IMPORT LICENSE N. 24/1/2463/1/2024 DEL 05/05/2024 AUT. ESPORTAZIONE MULTIPLA N. 6B/2024/2M RILASCIATA IL 30/07/2024 (LICENZA DI SCARICO N. 6B/2024/1S RILASCIATA IL N. /11/2024)
A115: 2445 | B115: =+VLOOKUP($A115,MAGAZZINO!$B$2:$M$100000,2,FALSE) | C115: =+VLOOKUP($A115,MAGAZZINO!$B$2:$M$100000,3,FALSE) | D115: =+VLOOKUP($A115,MAGAZZINO!$B$2:$M$100000,4,FALSE) | E115: =+VLOOKUP($A115,MAGAZZINO!$B$2:$M$100000,5,FALSE) | F115: =+VLOOKUP($A115,MAGAZZINO!$B$2:$M$100000,6,FALSE) | G115: =+VLOOKUP($A115,MAGAZZINO!$B$2:$M$100000,7,FALSE) | H115: =+VLOOKUP($A115,MAGAZZINO!$B$2:$M$100000,8,FALSE) | I115: =+VLOOKUP($A115,MAGAZZINO!$B$2:$M$100000,9,FALSE) | J115: =+VLOOKUP($A115,MAGAZZINO!$B$2:$M$100000,10,FALSE) | K115: =+VLOOKUP($A115,MAGAZZINO!$B$2:$M$100000,11,FALSE) | L115: =+VLOOKUP($A115,MAGAZZINO!$B$2:$M$100000,12,FALSE) | N115: 45609 | O115: HS & LLC (OMAN) | P115: IMPORT LICENSE N. 24/1/2463/1/2024 DEL 05/05/2024 AUT. ESPORTAZIONE MULTIPLA N. 6B/2024/2M RILASCIATA IL 30/07/2024 (LICENZA DI SCARICO N. 6B/2024/1S RILASCIATA IL 06/11/2024)
A116: 2446 | B116: =+VLOOKUP($A116,MAGAZZINO!$B$2:$M$100000,2,FALSE) | C116: =+VLOOKUP($A116,MAGAZZINO!$B$2:$M$100000,3,FALSE) | D116: =+VLOOKUP($A116,MAGAZZINO!$B$2:$M$100000,4,FALSE) | E116: =+VLOOKUP($A116,MAGAZZINO!$B$2:$M$100000,5,FALSE) | F116: =+VLOOKUP($A116,MAGAZZINO!$B$2:$M$100000,6,FALSE) | G116: =+VLOOKUP($A116,MAGAZZINO!$B$2:$M$100000,7,FALSE) | H116: =+VLOOKUP($A116,MAGAZZINO!$B$2:$M$100000,8,FALSE) | I116: =+VLOOKUP($A116,MAGAZZINO!$B$2:$M$100000,9,FALSE) | J116: =+VLOOKUP($A116,MAGAZZINO!$B$2:$M$100000,10,FALSE) | K116: =+VLOOKUP($A116,MAGAZZINO!$B$2:$M$100000,11,FALSE) | L116: =+VLOOKUP($A116,MAGAZZINO!$B$2:$M$100000,12,FALSE) | N116: 45609 | O116: HS & LLC (OMAN) | P116: IMPORT LICENSE N. 24/1/2463/1/2024 DEL 05/05/2024 AUT. ESPORTAZIONE MULTIPLA N. 6B/2024/2M RILASCIATA IL 30/07/2024 (LICENZA DI SCARICO N. 6B/2024/1S RILASCIATA IL 06/11/2024)
A117: 2447 | B117: =+VLOOKUP($A117,MAGAZZINO!$B$2:$M$100000,2,FALSE) | C117: =+VLOOKUP($A117,MAGAZZINO!$B$2:$M$100000,3,FALSE) | D117: =+VLOOKUP($A117,MAGAZZINO!$B$2:$M$100000,4,FALSE) | E117: =+VLOOKUP($A117,MAGAZZINO!$B$2:$M$100000,5,FALSE) | F117: =+VLOOKUP($A117,MAGAZZINO!$B$2:$M$100000,6,FALSE) | G117: =+VLOOKUP($A117,MAGAZZINO!$B$2:$M$100000,7,FALSE) | H117: =+VLOOKUP($A117,MAGAZZINO!$B$2:$M$100000,8,FALSE) | I117: =+VLOOKUP($A117,MAGAZZINO!$B$2:$M$100000,9,FALSE) | J117: =+VLOOKUP($A117,MAGAZZINO!$B$2:$M$100000,10,FALSE) | K117: =+VLOOKUP($A117,MAGAZZINO!$B$2:$M$100000,11,FALSE) | L117: =+VLOOKUP($A117,MAGAZZINO!$B$2:$M$100000,12,FALSE) | N117: 45609 | O117: HS & LLC (OMAN) | P117: IMPORT LICENSE N. 24/1/2463/1/2024 DEL 05/05/2024 AUT. ESPORTAZIONE MULTIPLA N. 6B/2024/2M RILASCIATA IL 30/07/2024 (LICENZA DI SCARICO N. 6B/2024/1S RILASCIATA IL 06/11/2024)
